Workbook

Sheet 대시보드
A1: 📊 가계 재무 대시보드
A2: 조회월만 바꾸면 핵심 숫자가 자동으로 바뀝니다. 단위: 만원
A4: 조회월(1~12) | B4: 7 | G4: 작성법
G5: 1) B4에 조회월을 입력하세요.
A6: 총지출 | B6: =CHOOSE($B$4,'01월'!C22,'02월'!C22,'03월'!C22,'04월'!C22,'05월'!C22,'06월'!C22,'07월'!C23,'08월'!C23,'09월'!C23,'10월'!C23,'11월'!C23,'12월'!C23) -> 2213768 | D6: 연간 총수입 | E6: =SUM('연간현황'!H5:H16) -> 34759585 | G6: 2) 총지출/잔여예산/순자산은 자동 계산됩니다.
A7: 목표지출 | B7: =CHOOSE($B$4,'01월'!B22,'02월'!B22,'03월'!B22,'04월'!B22,'05월'!B22,'06월'!B22,'07월'!B23,'08월'!B23,'09월'!B23,'10월'!B23,'11월'!B23,'12월'!B23) -> 6880000 | D7: 연간 총지출 | E7: =SUM('연간현황'!B5:B16) -> 13401426 | G7: 3) 월별 상세는 해당 월 시트에서 확인하세요.
A8: 잔여예산 | B8: =B7-B6 -> 4666232 | D8: 연간 마통상환 | E8: =SUM('연간현황'!C5:C16) -> 0 | G8: 4) 단위는 모두 만원입니다.
A9: 사용률 | B9: =IFERROR(B6/B7,0) -> 0.3217686 | D9: 연간 잔액차이 | E9: =SUM('연간현황'!D5:D16) -> 21358159
A10: 마통상환 | B10: {=IF($B$4<=1,"",INDEX('총자산'!$B$36:$M$36,1,$B$4-1)-INDEX('총자산'!$B$36:$M$36,1,$B$4))} -> 0 | G10: 월 | H10: 총지출 | I10: 총수입 | J10: 마통상환 | K10: 순자산
A11: 순자산 | B11: {=INDEX('총자산'!$B$38:$M$38,1,$B$4)} -> 0 | G11: 1월 | H11: ='연간현황'!B5 -> 0 | I11: ='연간현황'!H5 -> 0 | J11: ='연간현황'!C5 | K11: ='총자산'!B38 -> 0
G12: 2월 | H12: ='연간현황'!B6 -> 0 | I12: ='연간현황'!H6 -> 0 | J12: ='연간현황'!C6 -> 0 | K12: ='총자산'!C38 -> 0
G13: 3월 | H13: ='연간현황'!B7 -> 0 | I13: ='연간현황'!H7 -> 0 | J13: ='연간현황'!C7 -> 0 | K13: ='총자산'!D38 -> 0
G14: 4월 | H14: ='연간현황'!B8 -> 0 | I14: ='연간현황'!H8 -> 0 | J14: ='연간현황'!C8 -> 0 | K14: ='총자산'!E38 -> 0
G15: 5월 | H15: ='연간현황'!B9 -> 5285894 | I15: ='연간현황'!H9 -> 15427579 | J15: ='연간현황'!C9 -> 0 | K15: ='총자산'!F38 -> 806149475
G16: 6월 | H16: ='연간현황'!B10 -> 5901764 | I16: ='연간현황'!H10 -> 16521044 | J16: ='연간현황'!C10 -> 0 | K16: ='총자산'!G38 -> 818765242
G17: 7월 | H17: ='연간현황'!B11 -> 2213768 | I17: ='연간현황'!H11 -> 2810962 | J17: ='연간현황'!C11 -> 0 | K17: ='총자산'!H38 -> 0
G18: 8월 | H18: ='연간현황'!B12 -> 0 | I18: ='연간현황'!H12 -> 0 | J18: ='연간현황'!C12 -> 0 | K18: ='총자산'!I38 -> 0
G19: 9월 | H19: ='연간현황'!B13 -> 0 | I19: ='연간현황'!H13 -> 0 | J19: ='연간현황'!C13 -> 0 | K19: ='총자산'!J38 -> 0
G20: 10월 | H20: ='연간현황'!B14 -> 0 | I20: ='연간현황'!H14 -> 0 | J20: ='연간현황'!C14 -> 0 | K20: ='총자산'!K38 -> 0
G21: 11월 | H21: ='연간현황'!B15 -> 0 | I21: ='연간현황'!H15 -> 0 | J21: ='연간현황'!C15 -> 0 | K21: ='총자산'!L38 -> 0
G22: 12월 | H22: ='연간현황'!B16 -> 0 | I22: ='연간현황'!H16 -> 0 | J22: ='연간현황'!C16 -> 0 | K22: ='총자산'!M38 -> 0

Sheet 연간현황
A1: 연간현황 (컨트롤 타워)
A2: 기준년도와 연간 흐름을 관리합니다. 단위: 만원
A3: 기준년도 | B3: 2026 | L3: 작성법
A4: 월 | B4: 총지출 | C4: 마통상환 | D4: 차이 | E4: 기석수입 | F4: 승주수입 | G4: 기타수입 | H4: 총수입 | I4: 지출률 | J4: 메모 | L4: 1) B3 기준년도만 바꾸면 월별 집계 날짜가 자동 변경됩니다.
A5: 1월 | B5: ='01월'!C22 -> 0 | D5: =H5-B5-IF(C5="",0,C5) -> 0 | E5: ='수입관리'!D5 -> 0 | F5: ='수입관리'!G5 -> 0 | G5: ='수입관리'!H5 -> 0 | H5: ='수입관리'!I5 -> 0 | I5: =IFERROR(B5/CHOOSE(1,'01월'!B22,'02월'!B22,'03월'!B22,'04월'!B22,'05월'!B22,'06월'!B22,'07월'!B23,'08월'!B23,'09월'!B23,'10월'!B23,'11월'!B23,'12월'!B23),0) -> 0 | L5: 2) 총지출은 월별 시트 합계를 자동 연결합니다.
A6: 2월 | B6: ='02월'!C22 -> 0 | C6: ='총자산'!B36-'총자산'!C36 -> 0 | D6: =H6-B6-IF(C6="",0,C6) -> 0 | E6: ='수입관리'!D6 -> 0 | F6: ='수입관리'!G6 -> 0 | G6: ='수입관리'!H6 -> 0 | H6: ='수입관리'!I6 -> 0 | I6: =IFERROR(B6/CHOOSE(2,'01월'!B22,'02월'!B22,'03월'!B22,'04월'!B22,'05월'!B22,'06월'!B22,'07월'!B23,'08월'!B23,'09월'!B23,'10월'!B23,'11월'!B23,'12월'!B23),0) -> 0 | L6: 3) 마통상환은 총자산 시트의 전월 마통잔액-당월 마통잔액입니다.
A7: 3월 | B7: ='03월'!C22 -> 0 | C7: ='총자산'!C36-'총자산'!D36 -> 0 | D7: =H7-B7-IF(C7="",0,C7) -> 0 | E7: ='수입관리'!D7 -> 0 | F7: ='수입관리'!G7 -> 0 | G7: ='수입관리'!H7 -> 0 | H7: ='수입관리'!I7 -> 0 | I7: =IFERROR(B7/CHOOSE(3,'01월'!B22,'02월'!B22,'03월'!B22,'04월'!B22,'05월'!B22,'06월'!B22,'07월'!B23,'08월'!B23,'09월'!B23,'10월'!B23,'11월'!B23,'12월'!B23),0) -> 0 | L7: 4) 차이는 총수입-총지출-마통상환입니다.
A8: 4월 | B8: ='04월'!C22 -> 0 | C8: ='총자산'!D36-'총자산'!E36 -> 0 | D8: =H8-B8-IF(C8="",0,C8) -> 0 | E8: ='수입관리'!D8 -> 0 | F8: ='수입관리'!G8 -> 0 | G8: ='수입관리'!H8 -> 0 | H8: ='수입관리'!I8 -> 0 | I8: =IFERROR(B8/CHOOSE(4,'01월'!B22,'02월'!B22,'03월'!B22,'04월'!B22,'05월'!B22,'06월'!B22,'07월'!B23,'08월'!B23,'09월'!B23,'10월'!B23,'11월'!B23,'12월'!B23),0) -> 0
A9: 5월 | B9: ='05월'!C22 -> 5285894 | C9: ='총자산'!E36-'총자산'!F36 -> 0 | D9: =H9-B9-IF(C9="",0,C9) -> 10141685 | E9: ='수입관리'!D9 -> 9697711 | F9: ='수입관리'!G9 -> 5359916 | G9: ='수입관리'!H9 -> 369952 | H9: ='수입관리'!I9 -> 15427579 | I9: =IFERROR(B9/CHOOSE(5,'01월'!B22,'02월'!B22,'03월'!B22,'04월'!B22,'05월'!B22,'06월'!B22,'07월'!B23,'08월'!B23,'09월'!B23,'10월'!B23,'11월'!B23,'12월'!B23),0) -> 0.7616562
A10: 6월 | B10: ='06월'!C22 -> 5901764 | C10: ='총자산'!F36-'총자산'!G36 -> 0 | D10: =H10-B10-IF(C10="",0,C10) -> 10619280 | E10: ='수입관리'!D10 -> 7652000 | F10: ='수입관리'!G10 -> 8158923 | G10: ='수입관리'!H10 -> 710121 | H10: ='수입관리'!I10 -> 16521044 | I10: =IFERROR(B10/CHOOSE(6,'01월'!B22,'02월'!B22,'03월'!B22,'04월'!B22,'05월'!B22,'06월'!B22,'07월'!B23,'08월'!B23,'09월'!B23,'10월'!B23,'11월'!B23,'12월'!B23),0) -> 0.87046667
A11: 7월 | B11: ='07월'!C23 -> 2213768 | C11: ='총자산'!G36-'총자산'!H36 -> 0 | D11: =H11-B11-IF(C11="",0,C11) -> 597194 | E11: ='수입관리'!D11 -> 0 | F11: ='수입관리'!G11 -> 2200000 | G11: ='수입관리'!H11 -> 610962 | H11: ='수입관리'!I11 -> 2810962 | I11: =IFERROR(B11/CHOOSE(7,'01월'!B22,'02월'!B22,'03월'!B22,'04월'!B22,'05월'!B22,'06월'!B22,'07월'!B23,'08월'!B23,'09월'!B23,'10월'!B23,'11월'!B23,'12월'!B23),0) -> 0.3217686
A12: 8월 | B12: ='08월'!C23 -> 0 | C12: ='총자산'!H36-'총자산'!I36 -> 0 | D12: =H12-B12-IF(C12="",0,C12) -> 0 | E12: ='수입관리'!D12 -> 0 | F12: ='수입관리'!G12 -> 0 | G12: ='수입관리'!H12 -> 0 | H12: ='수입관리'!I12 -> 0 | I12: =IFERROR(B12/CHOOSE(8,'01월'!B22,'02월'!B22,'03월'!B22,'04월'!B22,'05월'!B22,'06월'!B22,'07월'!B23,'08월'!B23,'09월'!B23,'10월'!B23,'11월'!B23,'12월'!B23),0) -> 0
A13: 9월 | B13: ='09월'!C23 -> 0 | C13: ='총자산'!I36-'총자산'!J36 -> 0 | D13: =H13-B13-IF(C13="",0,C13) -> 0 | E13: ='수입관리'!D13 -> 0 | F13: ='수입관리'!G13 -> 0 | G13: ='수입관리'!H13 -> 0 | H13: ='수입관리'!I13 -> 0 | I13: =IFERROR(B13/CHOOSE(9,'01월'!B22,'02월'!B22,'03월'!B22,'04월'!B22,'05월'!B22,'06월'!B22,'07월'!B23,'08월'!B23,'09월'!B23,'10월'!B23,'11월'!B23,'12월'!B23),0) -> 0
A14: 10월 | B14: ='10월'!C23 -> 0 | C14: ='총자산'!J36-'총자산'!K36 -> 0 | D14: =H14-B14-IF(C14="",0,C14) -> 0 | E14: ='수입관리'!D14 -> 0 | F14: ='수입관리'!G14 -> 0 | G14: ='수입관리'!H14 -> 0 | H14: ='수입관리'!I14 -> 0 | I14: =IFERROR(B14/CHOOSE(10,'01월'!B22,'02월'!B22,'03월'!B22,'04월'!B22,'05월'!B22,'06월'!B22,'07월'!B23,'08월'!B23,'09월'!B23,'10월'!B23,'11월'!B23,'12월'!B23),0) -> 0
A15: 11월 | B15: ='11월'!C23 -> 0 | C15: ='총자산'!K36-'총자산'!L36 -> 0 | D15: =H15-B15-IF(C15="",0,C15) -> 0 | E15: ='수입관리'!D15 -> 0 | F15: ='수입관리'!G15 -> 0 | G15: ='수입관리'!H15 -> 0 | H15: ='수입관리'!I15 -> 0 | I15: =IFERROR(B15/CHOOSE(11,'01월'!B22,'02월'!B22,'03월'!B22,'04월'!B22,'05월'!B22,'06월'!B22,'07월'!B23,'08월'!B23,'09월'!B23,'10월'!B23,'11월'!B23,'12월'!B23),0) -> 0
A16: 12월 | B16: ='12월'!C23 -> 0 | C16: ='총자산'!L36-'총자산'!M36 -> 0 | D16: =H16-B16-IF(C16="",0,C16) -> 0 | E16: ='수입관리'!D16 -> 0 | F16: ='수입관리'!G16 -> 0 | G16: ='수입관리'!H16 -> 0 | H16: ='수입관리'!I16 -> 0 | I16: =IFERROR(B16/CHOOSE(12,'01월'!B22,'02월'!B22,'03월'!B22,'04월'!B22,'05월'!B22,'06월'!B22,'07월'!B23,'08월'!B23,'09월'!B23,'10월'!B23,'11월'!B23,'12월'!B23),0) -> 0
A17: 합계/평균 | B17: =SUM(B5:B16) -> 13401426 | C17: =SUM(C5:C16) -> 0 | D17: =SUM(D5:D16) -> 21358159 | E17: =SUM(E5:E16) -> 17349711 | F17: =SUM(F5:F16) -> 15718839 | G17: =SUM(G5:G16) -> 1691035 | H17: =SUM(H5:H16) -> 34759585 | I17: =AVERAGE(I5:I16) -> 0.16282429

Sheet 총자산
A1: 총자산 현황
A2: 매월 말 기준 자산/부채를 입력합니다. 계좌명은 자유롭게 수정하고, 현금 계좌 입력 영역의 빈 줄을 사용하세요. 단위: 원
A4: 항목 | B4: 1월 | C4: 2월 | D4: 3월 | E4: 4월 | F4: 5월 | G4: 6월 | H4: 7월 | I4: 8월 | J4: 9월 | K4: 10월 | L4: 11월 | M4: 12월 | O4: 작성법
A5: 현금 계좌 입력 영역 | O5: 1) 매월 말 기준으로 월별 금액을 입력하세요.
A6: 기업은행(기석) | F6: 0 | G6: 0 | O6: 2) 현금 계좌명은 A열에서 직접 수정하세요.
A7: 하나은행(기석) | F7: 4900 | G7: 83127 | O7: 3) 계좌가 늘면 현금 계좌 입력 영역의 빈 행을 사용하세요.
A8: 케이뱅크(기석) | F8: 18906 | G8: 66454 | O8: 4) 빈 행이 부족하면 현금합계 바로 위에서 행 삽입하세요.
A9: 기업은행(승주) | F9: 0 | G9: 90176 | O9: 5) 자산합계/부채합계/순자산/투자비중은 자동 계산됩니다.
A10: 우리은행(승주) | F10: 402572 | G10: 244382
A11: 부산은행(승주) | F11: 100000 | G11: 100000
A12: 케이뱅크(승주) | F12: 33862 | G12: 23766
A13: 미래에셋CMA | F13: 52909713 | G13: 36493386
A14: 기업은행중금채 | F14: 1843037 | G14: 1843037
A15: 하나은행적금 | F15: 1200000 | G15: 0
A16: 우리은행적금 | F16: 1000000 | G16: 1200000
A17: 주택청약(기석) | F17: 16500000 | G17: 16520000
A18: 주택청약(승주) | F18: 9600000 | G18: 9620000
A19: 부산은행예금 | F19: 1500000 | G19: 1500000
A20: 현금합계 | B20: =SUM(B6:B19) -> 0 | C20: =SUM(C6:C19) -> 0 | D20: =SUM(D6:D19) -> 0 | E20: =SUM(E6:E19) -> 0 | F20: =SUM(F6:F19) -> 85112990 | G20: =SUM(G6:G19) -> 67784328 | H20: =SUM(H6:H19) -> 0 | I20: =SUM(I6:I19) -> 0 | ... M20: =SUM(M6:M19) -> 0
A22: 투자/자산 입력 영역
A23: 토스증권(기석) | F23: 1553072 | G23: 1556891
A24: 미래에셋(기석) | F24: 2228257 | G24: 2263753
A25: 업비트(기석) | F25: 1689552 | G25: 1400848
A26: 농협투자(승주) | F26: 10104034 | G26: 9859550
A27: 토스증권(승주) | F27: 189308 | G27: 158673
A28: 퇴직연금(기석) | F28: 28962461 | G28: 28747516
A29: 퇴직연금(승주) | F29: 20000000 | G29: 20000000
A30: 부동산 | F30: 921900000 | G30: 951900000
A31: 투자합계 | B31: =SUM(B23:B30) -> 0 | C31: =SUM(C23:C30) -> 0 | D31: =SUM(D23:D30) -> 0 | E31: =SUM(E23:E30) -> 0 | F31: =SUM(F23:F30) -> 986626684 | G31: =SUM(G23:G30) -> 1015887231 | H31: =SUM(H23:H30) -> 0 | I31: =SUM(I23:I30) -> 0 | ... M31: =SUM(M23:M30) -> 0
A32: 자산합계 | B32: =B20+B31 -> 0 | C32: =C20+C31 -> 0 | D32: =D20+D31 -> 0 | E32: =E20+E31 -> 0 | F32: =F20+F31 -> 1071739674 | G32: =G20+G31 -> 1083671559 | H32: =H20+H31 -> 0 | I32: =I20+I31 -> 0 | ... M32: =M20+M31 -> 0
A34: 부채 입력 영역
A35: 주담대 | F35: 265590199 | G35: 264906317
A36: 마통 | F36: 0 | G36: 0
A37: 부채합계 | B37: =SUM(B35:B36) -> 0 | C37: =SUM(C35:C36) -> 0 | D37: =SUM(D35:D36) -> 0 | E37: =SUM(E35:E36) -> 0 | F37: =SUM(F35:F36) -> 265590199 | G37: =SUM(G35:G36) -> 264906317 | H37: =SUM(H35:H36) -> 0 | I37: =SUM(I35:I36) -> 0 | ... M37: =SUM(M35:M36) -> 0
A38: 순자산 | B38: =B32-B37 -> 0 | C38: =C32-C37 -> 0 | D38: =D32-D37 -> 0 | E38: =E32-E37 -> 0 | F38: =F32-F37 -> 806149475 | G38: =G32-G37 -> 818765242 | H38: =H32-H37 -> 0 | I38: =I32-I37 -> 0 | ... M38: =M32-M37 -> 0
A39: 투자비중 | B39: =IFERROR(SUM(B23:B29)/B32,0) -> 0 | C39: =IFERROR(SUM(C23:C29)/C32,0) -> 0 | D39: =IFERROR(SUM(D23:D29)/D32,0) -> 0 | E39: =IFERROR(SUM(E23:E29)/E32,0) -> 0 | F39: =IFERROR(SUM(F23:F29)/F32,0) -> 0.060394036 | G39: =IFERROR(SUM(G23:G29)/G32,0) -> 0.059046701 | H39: =IFERROR(SUM(H23:H29)/H32,0) -> 0 | I39: =IFERROR(SUM(I23:I29)/I32,0) -> 0 | ... M39: =IFERROR(SUM(M23:M29)/M32,0) -> 0
A43: 월 | B43: 자산합계 | C43: 부채합계 | D43: 순자산 | E43: 투자비중
A44: 1월 | B44: =B32 -> 0 | C44: =B37 -> 0 | D44: =B38 -> 0 | E44: =B39 -> 0
A45: 2월 | B45: =C32 -> 0 | C45: =C37 -> 0 | D45: =C38 -> 0 | E45: =C39 -> 0
A46: 3월 | B46: =D32 -> 0 | C46: =D37 -> 0 | D46: =D38 -> 0 | E46: =D39 -> 0
...

Sheet 수입관리
A1: 수입관리 (자동집계)
A2: 내역 시트에서 타입=수입, 대분류=기석월급/기석상여/승주월급/승주상여/기타수입을 월별 자동 집계합니다. 단위: 원
A4: 월 | B4: 기석월급 | C4: 기석상여 | D4: 기석수입 | E4: 승주월급 | F4: 승주상여 | G4: 승주수입 | H4: 기타수입 | I4: 총수입 | K4: 작성법
A5: 1월 | B5: =IFERROR(SUMIFS('내역'!$E:$E,'내역'!$B:$B,"수입",'내역'!$C:$C,B$4,'내역'!$A:$A,">="&DATE('연간현황'!$B$3,1,1),'내역'!$A:$A,"<="&EOMONTH(DATE('연간현황'!$B$3,1,1),0)),0) -> 0 | C5: =IFERROR(SUMIFS('내역'!$E:$E,'내역'!$B:$B,"수입",'내역'!$C:$C,C$4,'내역'!$A:$A,">="&DATE('연간현황'!$B$3,1,1),'내역'!$A:$A,"<="&EOMONTH(DATE('연간현황'!$B$3,1,1),0)),0) -> 0 | D5: =SUM(B5:C5) -> 0 | E5: =IFERROR(SUMIFS('내역'!$E:$E,'내역'!$B:$B,"수입",'내역'!$C:$C,E$4,'내역'!$A:$A,">="&DATE('연간현황'!$B$3,1,1),'내역'!$A:$A,"<="&EOMONTH(DATE('연간현황'!$B$3,1,1),0)),0) -> 0 | F5: =IFERROR(SUMIFS('내역'!$E:$E,'내역'!$B:$B,"수입",'내역'!$C:$C,F$4,'내역'!$A:$A,">="&DATE('연간현황'!$B$3,1,1),'내역'!$A:$A,"<="&EOMONTH(DATE('연간현황'!$B$3,1,1),0)),0) -> 0 | G5: =SUM(E5:F5) -> 0 | H5: =IFERROR(SUMIFS('내역'!$E:$E,'내역'!$B:$B,"수입",'내역'!$C:$C,H$4,'내역'!$A:$A,">="&DATE('연간현황'!$B$3,1,1),'내역'!$A:$A,"<="&EOMONTH(DATE('연간현황'!$B$3,1,1),0)),0) -> 0 | I5: =SUM(D5,G5,H5) -> 0 | K5: 1) 내역 시트에 수입 내역도 함께 붙여넣기
A6: 2월 | B6: =IFERROR(SUMIFS('내역'!$E:$E,'내역'!$B:$B,"수입",'내역'!$C:$C,B$4,'내역'!$A:$A,">="&DATE('연간현황'!$B$3,2,1),'내역'!$A:$A,"<="&EOMONTH(DATE('연간현황'!$B$3,2,1),0)),0) -> 0 | C6: =IFERROR(SUMIFS('내역'!$E:$E,'내역'!$B:$B,"수입",'내역'!$C:$C,C$4,'내역'!$A:$A,">="&DATE('연간현황'!$B$3,2,1),'내역'!$A:$A,"<="&EOMONTH(DATE('연간현황'!$B$3,2,1),0)),0) -> 0 | D6: =SUM(B6:C6) -> 0 | E6: =IFERROR(SUMIFS('내역'!$E:$E,'내역'!$B:$B,"수입",'내역'!$C:$C,E$4,'내역'!$A:$A,">="&DATE('연간현황'!$B$3,2,1),'내역'!$A:$A,"<="&EOMONTH(DATE('연간현황'!$B$3,2,1),0)),0) -> 0 | F6: =IFERROR(SUMIFS('내역'!$E:$E,'내역'!$B:$B,"수입",'내역'!$C:$C,F$4,'내역'!$A:$A,">="&DATE('연간현황'!$B$3,2,1),'내역'!$A:$A,"<="&EOMONTH(DATE('연간현황'!$B$3,2,1),0)),0) -> 0 | G6: =SUM(E6:F6) -> 0 | H6: =IFERROR(SUMIFS('내역'!$E:$E,'내역'!$B:$B,"수입",'내역'!$C:$C,H$4,'내역'!$A:$A,">="&DATE('연간현황'!$B$3,2,1),'내역'!$A:$A,"<="&EOMONTH(DATE('연간현황'!$B$3,2,1),0)),0) -> 0 | I6: =SUM(D6,G6,H6) -> 0 | K6: 2) 타입은 반드시 "수입"
A7: 3월 | B7: =IFERROR(SUMIFS('내역'!$E:$E,'내역'!$B:$B,"수입",'내역'!$C:$C,B$4,'내역'!$A:$A,">="&DATE('연간현황'!$B$3,3,1),'내역'!$A:$A,"<="&EOMONTH(DATE('연간현황'!$B$3,3,1),0)),0) -> 0 | C7: =IFERROR(SUMIFS('내역'!$E:$E,'내역'!$B:$B,"수입",'내역'!$C:$C,C$4,'내역'!$A:$A,">="&DATE('연간현황'!$B$3,3,1),'내역'!$A:$A,"<="&EOMONTH(DATE('연간현황'!$B$3,3,1),0)),0) -> 0 | D7: =SUM(B7:C7) -> 0 | E7: =IFERROR(SUMIFS('내역'!$E:$E,'내역'!$B:$B,"수입",'내역'!$C:$C,E$4,'내역'!$A:$A,">="&DATE('연간현황'!$B$3,3,1),'내역'!$A:$A,"<="&EOMONTH(DATE('연간현황'!$B$3,3,1),0)),0) -> 0 | F7: =IFERROR(SUMIFS('내역'!$E:$E,'내역'!$B:$B,"수입",'내역'!$C:$C,F$4,'내역'!$A:$A,">="&DATE('연간현황'!$B$3,3,1),'내역'!$A:$A,"<="&EOMONTH(DATE('연간현황'!$B$3,3,1),0)),0) -> 0 | G7: =SUM(E7:F7) -> 0 | H7: =IFERROR(SUMIFS('내역'!$E:$E,'내역'!$B:$B,"수입",'내역'!$C:$C,H$4,'내역'!$A:$A,">="&DATE('연간현황'!$B$3,3,1),'내역'!$A:$A,"<="&EOMONTH(DATE('연간현황'!$B$3,3,1),0)),0) -> 0 | I7: =SUM(D7,G7,H7) -> 0 | K7: 3) 대분류는 5개 중 하나로 통일
A8: 4월 | B8: =IFERROR(SUMIFS('내역'!$E:$E,'내역'!$B:$B,"수입",'내역'!$C:$C,B$4,'내역'!$A:$A,">="&DATE('연간현황'!$B$3,4,1),'내역'!$A:$A,"<="&EOMONTH(DATE('연간현황'!$B$3,4,1),0)),0) -> 0 | C8: =IFERROR(SUMIFS('내역'!$E:$E,'내역'!$B:$B,"수입",'내역'!$C:$C,C$4,'내역'!$A:$A,">="&DATE('연간현황'!$B$3,4,1),'내역'!$A:$A,"<="&EOMONTH(DATE('연간현황'!$B$3,4,1),0)),0) -> 0 | D8: =SUM(B8:C8) -> 0 | E8: =IFERROR(SUMIFS('내역'!$E:$E,'내역'!$B:$B,"수입",'내역'!$C:$C,E$4,'내역'!$A:$A,">="&DATE('연간현황'!$B$3,4,1),'내역'!$A:$A,"<="&EOMONTH(DATE('연간현황'!$B$3,4,1),0)),0) -> 0 | F8: =IFERROR(SUMIFS('내역'!$E:$E,'내역'!$B:$B,"수입",'내역'!$C:$C,F$4,'내역'!$A:$A,">="&DATE('연간현황'!$B$3,4,1),'내역'!$A:$A,"<="&EOMONTH(DATE('연간현황'!$B$3,4,1),0)),0) -> 0 | G8: =SUM(E8:F8) -> 0 | H8: =IFERROR(SUMIFS('내역'!$E:$E,'내역'!$B:$B,"수입",'내역'!$C:$C,H$4,'내역'!$A:$A,">="&DATE('연간현황'!$B$3,4,1),'내역'!$A:$A,"<="&EOMONTH(DATE('연간현황'!$B$3,4,1),0)),0) -> 0 | I8: =SUM(D8,G8,H8) -> 0 | K8: 기석월급/기석상여/승주월급/승주상여/기타수입
A9: 5월 | B9: =IFERROR(SUMIFS('내역'!$E:$E,'내역'!$B:$B,"수입",'내역'!$C:$C,B$4,'내역'!$A:$A,">="&DATE('연간현황'!$B$3,5,1),'내역'!$A:$A,"<="&EOMONTH(DATE('연간현황'!$B$3,5,1),0)),0) -> 6078411 | C9: =IFERROR(SUMIFS('내역'!$E:$E,'내역'!$B:$B,"수입",'내역'!$C:$C,C$4,'내역'!$A:$A,">="&DATE('연간현황'!$B$3,5,1),'내역'!$A:$A,"<="&EOMONTH(DATE('연간현황'!$B$3,5,1),0)),0) -> 3619300 | D9: =SUM(B9:C9) -> 9697711 | E9: =IFERROR(SUMIFS('내역'!$E:$E,'내역'!$B:$B,"수입",'내역'!$C:$C,E$4,'내역'!$A:$A,">="&DATE('연간현황'!$B$3,5,1),'내역'!$A:$A,"<="&EOMONTH(DATE('연간현황'!$B$3,5,1),0)),0) -> 5359916 | F9: =IFERROR(SUMIFS('내역'!$E:$E,'내역'!$B:$B,"수입",'내역'!$C:$C,F$4,'내역'!$A:$A,">="&DATE('연간현황'!$B$3,5,1),'내역'!$A:$A,"<="&EOMONTH(DATE('연간현황'!$B$3,5,1),0)),0) -> 0 | G9: =SUM(E9:F9) -> 5359916 | H9: =IFERROR(SUMIFS('내역'!$E:$E,'내역'!$B:$B,"수입",'내역'!$C:$C,H$4,'내역'!$A:$A,">="&DATE('연간현황'!$B$3,5,1),'내역'!$A:$A,"<="&EOMONTH(DATE('연간현황'!$B$3,5,1),0)),0) -> 369952 | I9: =SUM(D9,G9,H9) -> 15427579 | K9: 4) 포인트·이체·환급은 제외
A10: 6월 | B10: =IFERROR(SUMIFS('내역'!$E:$E,'내역'!$B:$B,"수입",'내역'!$C:$C,B$4,'내역'!$A:$A,">="&DATE('연간현황'!$B$3,6,1),'내역'!$A:$A,"<="&EOMONTH(DATE('연간현황'!$B$3,6,1),0)),0) -> 3984400 | C10: =IFERROR(SUMIFS('내역'!$E:$E,'내역'!$B:$B,"수입",'내역'!$C:$C,C$4,'내역'!$A:$A,">="&DATE('연간현황'!$B$3,6,1),'내역'!$A:$A,"<="&EOMONTH(DATE('연간현황'!$B$3,6,1),0)),0) -> 3667600 | D10: =SUM(B10:C10) -> 7652000 | E10: =IFERROR(SUMIFS('내역'!$E:$E,'내역'!$B:$B,"수입",'내역'!$C:$C,E$4,'내역'!$A:$A,">="&DATE('연간현황'!$B$3,6,1),'내역'!$A:$A,"<="&EOMONTH(DATE('연간현황'!$B$3,6,1),0)),0) -> 5628335 | F10: =IFERROR(SUMIFS('내역'!$E:$E,'내역'!$B:$B,"수입",'내역'!$C:$C,F$4,'내역'!$A:$A,">="&DATE('연간현황'!$B$3,6,1),'내역'!$A:$A,"<="&EOMONTH(DATE('연간현황'!$B$3,6,1),0)),0) -> 2530588 | G10: =SUM(E10:F10) -> 8158923 | H10: =IFERROR(SUMIFS('내역'!$E:$E,'내역'!$B:$B,"수입",'내역'!$C:$C,H$4,'내역'!$A:$A,">="&DATE('연간현황'!$B$3,6,1),'내역'!$A:$A,"<="&EOMONTH(DATE('연간현황'!$B$3,6,1),0)),0) -> 710121 | I10: =SUM(D10,G10,H10) -> 16521044
A11: 7월 | B11: =IFERROR(SUMIFS('내역'!$E:$E,'내역'!$B:$B,"수입",'내역'!$C:$C,B$4,'내역'!$A:$A,">="&DATE('연간현황'!$B$3,7,1),'내역'!$A:$A,"<="&EOMONTH(DATE('연간현황'!$B$3,7,1),0)),0) -> 0 | C11: =IFERROR(SUMIFS('내역'!$E:$E,'내역'!$B:$B,"수입",'내역'!$C:$C,C$4,'내역'!$A:$A,">="&DATE('연간현황'!$B$3,7,1),'내역'!$A:$A,"<="&EOMONTH(DATE('연간현황'!$B$3,7,1),0)),0) -> 0 | D11: =SUM(B11:C11) -> 0 | E11: =IFERROR(SUMIFS('내역'!$E:$E,'내역'!$B:$B,"수입",'내역'!$C:$C,E$4,'내역'!$A:$A,">="&DATE('연간현황'!$B$3,7,1),'내역'!$A:$A,"<="&EOMONTH(DATE('연간현황'!$B$3,7,1),0)),0) -> 2200000 | F11: =IFERROR(SUMIFS('내역'!$E:$E,'내역'!$B:$B,"수입",'내역'!$C:$C,F$4,'내역'!$A:$A,">="&DATE('연간현황'!$B$3,7,1),'내역'!$A:$A,"<="&EOMONTH(DATE('연간현황'!$B$3,7,1),0)),0) -> 0 | G11: =SUM(E11:F11) -> 2200000 | H11: =IFERROR(SUMIFS('내역'!$E:$E,'내역'!$B:$B,"수입",'내역'!$C:$C,H$4,'내역'!$A:$A,">="&DATE('연간현황'!$B$3,7,1),'내역'!$A:$A,"<="&EOMONTH(DATE('연간현황'!$B$3,7,1),0)),0) -> 610962 | I11: =SUM(D11,G11,H11) -> 2810962
A12: 8월 | B12: =IFERROR(SUMIFS('내역'!$E:$E,'내역'!$B:$B,"수입",'내역'!$C:$C,B$4,'내역'!$A:$A,">="&DATE('연간현황'!$B$3,8,1),'내역'!$A:$A,"<="&EOMONTH(DATE('연간현황'!$B$3,8,1),0)),0) -> 0 | C12: =IFERROR(SUMIFS('내역'!$E:$E,'내역'!$B:$B,"수입",'내역'!$C:$C,C$4,'내역'!$A:$A,">="&DATE('연간현황'!$B$3,8,1),'내역'!$A:$A,"<="&EOMONTH(DATE('연간현황'!$B$3,8,1),0)),0) -> 0 | D12: =SUM(B12:C12) -> 0 | E12: =IFERROR(SUMIFS('내역'!$E:$E,'내역'!$B:$B,"수입",'내역'!$C:$C,E$4,'내역'!$A:$A,">="&DATE('연간현황'!$B$3,8,1),'내역'!$A:$A,"<="&EOMONTH(DATE('연간현황'!$B$3,8,1),0)),0) -> 0 | F12: =IFERROR(SUMIFS('내역'!$E:$E,'내역'!$B:$B,"수입",'내역'!$C:$C,F$4,'내역'!$A:$A,">="&DATE('연간현황'!$B$3,8,1),'내역'!$A:$A,"<="&EOMONTH(DATE('연간현황'!$B$3,8,1),0)),0) -> 0 | G12: =SUM(E12:F12) -> 0 | H12: =IFERROR(SUMIFS('내역'!$E:$E,'내역'!$B:$B,"수입",'내역'!$C:$C,H$4,'내역'!$A:$A,">="&DATE('연간현황'!$B$3,8,1),'내역'!$A:$A,"<="&EOMONTH(DATE('연간현황'!$B$3,8,1),0)),0) -> 0 | I12: =SUM(D12,G12,H12) -> 0
A13: 9월 | B13: =IFERROR(SUMIFS('내역'!$E:$E,'내역'!$B:$B,"수입",'내역'!$C:$C,B$4,'내역'!$A:$A,">="&DATE('연간현황'!$B$3,9,1),'내역'!$A:$A,"<="&EOMONTH(DATE('연간현황'!$B$3,9,1),0)),0) -> 0 | C13: =IFERROR(SUMIFS('내역'!$E:$E,'내역'!$B:$B,"수입",'내역'!$C:$C,C$4,'내역'!$A:$A,">="&DATE('연간현황'!$B$3,9,1),'내역'!$A:$A,"<="&EOMONTH(DATE('연간현황'!$B$3,9,1),0)),0) -> 0 | D13: =SUM(B13:C13) -> 0 | E13: =IFERROR(SUMIFS('내역'!$E:$E,'내역'!$B:$B,"수입",'내역'!$C:$C,E$4,'내역'!$A:$A,">="&DATE('연간현황'!$B$3,9,1),'내역'!$A:$A,"<="&EOMONTH(DATE('연간현황'!$B$3,9,1),0)),0) -> 0 | F13: =IFERROR(SUMIFS('내역'!$E:$E,'내역'!$B:$B,"수입",'내역'!$C:$C,F$4,'내역'!$A:$A,">="&DATE('연간현황'!$B$3,9,1),'내역'!$A:$A,"<="&EOMONTH(DATE('연간현황'!$B$3,9,1),0)),0) -> 0 | G13: =SUM(E13:F13) -> 0 | H13: =IFERROR(SUMIFS('내역'!$E:$E,'내역'!$B:$B,"수입",'내역'!$C:$C,H$4,'내역'!$A:$A,">="&DATE('연간현황'!$B$3,9,1),'내역'!$A:$A,"<="&EOMONTH(DATE('연간현황'!$B$3,9,1),0)),0) -> 0 | I13: =SUM(D13,G13,H13) -> 0
A14: 10월 | B14: =IFERROR(SUMIFS('내역'!$E:$E,'내역'!$B:$B,"수입",'내역'!$C:$C,B$4,'내역'!$A:$A,">="&DATE('연간현황'!$B$3,10,1),'내역'!$A:$A,"<="&EOMONTH(DATE('연간현황'!$B$3,10,1),0)),0) -> 0 | C14: =IFERROR(SUMIFS('내역'!$E:$E,'내역'!$B:$B,"수입",'내역'!$C:$C,C$4,'내역'!$A:$A,">="&DATE('연간현황'!$B$3,10,1),'내역'!$A:$A,"<="&EOMONTH(DATE('연간현황'!$B$3,10,1),0)),0) -> 0 | D14: =SUM(B14:C14) -> 0 | E14: =IFERROR(SUMIFS('내역'!$E:$E,'내역'!$B:$B,"수입",'내역'!$C:$C,E$4,'내역'!$A:$A,">="&DATE('연간현황'!$B$3,10,1),'내역'!$A:$A,"<="&EOMONTH(DATE('연간현황'!$B$3,10,1),0)),0) -> 0 | F14: =IFERROR(SUMIFS('내역'!$E:$E,'내역'!$B:$B,"수입",'내역'!$C:$C,F$4,'내역'!$A:$A,">="&DATE('연간현황'!$B$3,10,1),'내역'!$A:$A,"<="&EOMONTH(DATE('연간현황'!$B$3,10,1),0)),0) -> 0 | G14: =SUM(E14:F14) -> 0 | H14: =IFERROR(SUMIFS('내역'!$E:$E,'내역'!$B:$B,"수입",'내역'!$C:$C,H$4,'내역'!$A:$A,">="&DATE('연간현황'!$B$3,10,1),'내역'!$A:$A,"<="&EOMONTH(DATE('연간현황'!$B$3,10,1),0)),0) -> 0 | I14: =SUM(D14,G14,H14) -> 0
A15: 11월 | B15: =IFERROR(SUMIFS('내역'!$E:$E,'내역'!$B:$B,"수입",'내역'!$C:$C,B$4,'내역'!$A:$A,">="&DATE('연간현황'!$B$3,11,1),'내역'!$A:$A,"<="&EOMONTH(DATE('연간현황'!$B$3,11,1),0)),0) -> 0 | C15: =IFERROR(SUMIFS('내역'!$E:$E,'내역'!$B:$B,"수입",'내역'!$C:$C,C$4,'내역'!$A:$A,">="&DATE('연간현황'!$B$3,11,1),'내역'!$A:$A,"<="&EOMONTH(DATE('연간현황'!$B$3,11,1),0)),0) -> 0 | D15: =SUM(B15:C15) -> 0 | E15: =IFERROR(SUMIFS('내역'!$E:$E,'내역'!$B:$B,"수입",'내역'!$C:$C,E$4,'내역'!$A:$A,">="&DATE('연간현황'!$B$3,11,1),'내역'!$A:$A,"<="&EOMONTH(DATE('연간현황'!$B$3,11,1),0)),0) -> 0 | F15: =IFERROR(SUMIFS('내역'!$E:$E,'내역'!$B:$B,"수입",'내역'!$C:$C,F$4,'내역'!$A:$A,">="&DATE('연간현황'!$B$3,11,1),'내역'!$A:$A,"<="&EOMONTH(DATE('연간현황'!$B$3,11,1),0)),0) -> 0 | G15: =SUM(E15:F15) -> 0 | H15: =IFERROR(SUMIFS('내역'!$E:$E,'내역'!$B:$B,"수입",'내역'!$C:$C,H$4,'내역'!$A:$A,">="&DATE('연간현황'!$B$3,11,1),'내역'!$A:$A,"<="&EOMONTH(DATE('연간현황'!$B$3,11,1),0)),0) -> 0 | I15: =SUM(D15,G15,H15) -> 0
A16: 12월 | B16: =IFERROR(SUMIFS('내역'!$E:$E,'내역'!$B:$B,"수입",'내역'!$C:$C,B$4,'내역'!$A:$A,">="&DATE('연간현황'!$B$3,12,1),'내역'!$A:$A,"<="&EOMONTH(DATE('연간현황'!$B$3,12,1),0)),0) -> 0 | C16: =IFERROR(SUMIFS('내역'!$E:$E,'내역'!$B:$B,"수입",'내역'!$C:$C,C$4,'내역'!$A:$A,">="&DATE('연간현황'!$B$3,12,1),'내역'!$A:$A,"<="&EOMONTH(DATE('연간현황'!$B$3,12,1),0)),0) -> 0 | D16: =SUM(B16:C16) -> 0 | E16: =IFERROR(SUMIFS('내역'!$E:$E,'내역'!$B:$B,"수입",'내역'!$C:$C,E$4,'내역'!$A:$A,">="&DATE('연간현황'!$B$3,12,1),'내역'!$A:$A,"<="&EOMONTH(DATE('연간현황'!$B$3,12,1),0)),0) -> 0 | F16: =IFERROR(SUMIFS('내역'!$E:$E,'내역'!$B:$B,"수입",'내역'!$C:$C,F$4,'내역'!$A:$A,">="&DATE('연간현황'!$B$3,12,1),'내역'!$A:$A,"<="&EOMONTH(DATE('연간현황'!$B$3,12,1),0)),0) -> 0 | G16: =SUM(E16:F16) -> 0 | H16: =IFERROR(SUMIFS('내역'!$E:$E,'내역'!$B:$B,"수입",'내역'!$C:$C,H$4,'내역'!$A:$A,">="&DATE('연간현황'!$B$3,12,1),'내역'!$A:$A,"<="&EOMONTH(DATE('연간현황'!$B$3,12,1),0)),0) -> 0 | I16: =SUM(D16,G16,H16) -> 0
A17: 합계 | B17: =SUM(B5:B16) -> 10062811 | C17: =SUM(C5:C16) -> 7286900 | D17: =SUM(D5:D16) -> 17349711 | E17: =SUM(E5:E16) -> 13188251 | F17: =SUM(F5:F16) -> 2530588 | G17: =SUM(G5:G16) -> 15718839 | H17: =SUM(H5:H16) -> 1691035 | I17: =SUM(I5:I16) -> 34759585

Sheet 01월
A1: 01월 한도 관리
A2: 내역 시트에 복붙하면 자동 집계됩니다. 단위: 원
A4: 월 예산 | B4: =B22 -> 6940000 | C4: 월 사용 | D4: =C22 -> 0 | E4: 잔여 | F4: =D22 -> 6940000 | G4: 총 사용률 | H4: =IFERROR(C22/B22,0) -> 0
A7: 항목 | B7: 예산 | C7: 사용 | D7: 남은금액 | E7: 사용률 | F7: 상태 | G7: 진행바 | I7: 위험 TOP3
A8: 대출 | B8: 2900000 | C8: =IFERROR(ABS(SUMIFS('내역'!E:E,'내역'!C:C,"대출",'내역'!A:A,">="&DATE('연간현황'!B3,1,1),'내역'!A:A,"<="&EOMONTH(DATE('연간현황'!B3,1,1),0))),0) -> 0 | D8: =B8-C8 -> 2900000 | E8: =IFERROR(C8/B8,0) -> 0 | F8: =IF(E8>=1,"초과",IF(E8>=0.8,"주의","안정")) -> 안정 | G8: =REPT("█",ROUND(MIN(1,E8)*10,0))&REPT("░",10-ROUND(MIN(1,E8)*10,0)) -> ░░░░░░░░░░ | I8: 순위 | J8: 항목 | K8: 사용률 | L8: 남은금액
A9: 보험 | B9: 550000 | C9: =IFERROR(ABS(SUMIFS('내역'!E:E,'내역'!C:C,"보험",'내역'!A:A,">="&DATE('연간현황'!B3,1,1),'내역'!A:A,"<="&EOMONTH(DATE('연간현황'!B3,1,1),0))),0) -> 0 | D9: =B9-C9 -> 550000 | E9: =IFERROR(C9/B9,0) -> 0 | F9: =IF(E9>=1,"초과",IF(E9>=0.8,"주의","안정")) -> 안정 | G9: =REPT("█",ROUND(MIN(1,E9)*10,0))&REPT("░",10-ROUND(MIN(1,E9)*10,0)) -> ░░░░░░░░░░ | I9: 1 | J9: {=INDEX($A$8:$A$21,MATCH(LARGE($E$8:$E$21,1),$E$8:$E$21,0))} -> 대출 | K9: =LARGE($E$8:$E$21,1) -> 0 | L9: {=INDEX($D$8:$D$21,MATCH(LARGE($E$8:$E$21,1),$E$8:$E$21,0))} -> 2900000
A10: 통신비 | B10: 140000 | C10: =IFERROR(ABS(SUMIFS('내역'!E:E,'내역'!C:C,"통신비",'내역'!A:A,">="&DATE('연간현황'!B3,1,1),'내역'!A:A,"<="&EOMONTH(DATE('연간현황'!B3,1,1),0))),0) -> 0 | D10: =B10-C10 -> 140000 | E10: =IFERROR(C10/B10,0) -> 0 | F10: =IF(E10>=1,"초과",IF(E10>=0.8,"주의","안정")) -> 안정 | G10: =REPT("█",ROUND(MIN(1,E10)*10,0))&REPT("░",10-ROUND(MIN(1,E10)*10,0)) -> ░░░░░░░░░░ | I10: 2 | J10: {=INDEX($A$8:$A$21,MATCH(LARGE($E$8:$E$21,2),$E$8:$E$21,0))} -> 대출 | K10: =LARGE($E$8:$E$21,2) -> 0 | L10: {=INDEX($D$8:$D$21,MATCH(LARGE($E$8:$E$21,2),$E$8:$E$21,0))} -> 2900000
A11: 주거비 | B11: 210000 | C11: =IFERROR(ABS(SUMIFS('내역'!E:E,'내역'!C:C,"주거비",'내역'!A:A,">="&DATE('연간현황'!B3,1,1),'내역'!A:A,"<="&EOMONTH(DATE('연간현황'!B3,1,1),0))),0) -> 0 | D11: =B11-C11 -> 210000 | E11: =IFERROR(C11/B11,0) -> 0 | F11: =IF(E11>=1,"초과",IF(E11>=0.8,"주의","안정")) -> 안정 | G11: =REPT("█",ROUND(MIN(1,E11)*10,0))&REPT("░",10-ROUND(MIN(1,E11)*10,0)) -> ░░░░░░░░░░ | I11: 3 | J11: {=INDEX($A$8:$A$21,MATCH(LARGE($E$8:$E$21,3),$E$8:$E$21,0))} -> 대출 | K11: =LARGE($E$8:$E$21,3) -> 0 | L11: {=INDEX($D$8:$D$21,MATCH(LARGE($E$8:$E$21,3),$E$8:$E$21,0))} -> 2900000
A12: 생활고정비 | B12: 260000 | C12: =IFERROR(ABS(SUMIFS('내역'!E:E,'내역'!C:C,"생활고정비",'내역'!A:A,">="&DATE('연간현황'!B3,1,1),'내역'!A:A,"<="&EOMONTH(DATE('연간현황'!B3,1,1),0))),0) -> 0 | D12: =B12-C12 -> 260000 | E12: =IFERROR(C12/B12,0) -> 0 | F12: =IF(E12>=1,"초과",IF(E12>=0.8,"주의","안정")) -> 안정 | G12: =REPT("█",ROUND(MIN(1,E12)*10,0))&REPT("░",10-ROUND(MIN(1,E12)*10,0)) -> ░░░░░░░░░░
A13: 금융고정비 | B13: 580000 | C13: =IFERROR(ABS(SUMIFS('내역'!E:E,'내역'!C:C,"금융고정비",'내역'!A:A,">="&DATE('연간현황'!B3,1,1),'내역'!A:A,"<="&EOMONTH(DATE('연간현황'!B3,1,1),0))),0) -> 0 | D13: =B13-C13 -> 580000 | E13: =IFERROR(C13/B13,0) -> 0 | F13: =IF(E13>=1,"초과",IF(E13>=0.8,"주의","안정")) -> 안정 | G13: =REPT("█",ROUND(MIN(1,E13)*10,0))&REPT("░",10-ROUND(MIN(1,E13)*10,0)) -> ░░░░░░░░░░ | I13: 작성법
A14: 교통 | B14: 150000 | C14: =IFERROR(ABS(SUMIFS('내역'!E:E,'내역'!C:C,"교통",'내역'!A:A,">="&DATE('연간현황'!B3,1,1),'내역'!A:A,"<="&EOMONTH(DATE('연간현황'!B3,1,1),0))),0) -> 0 | D14: =B14-C14 -> 150000 | E14: =IFERROR(C14/B14,0) -> 0 | F14: =IF(E14>=1,"초과",IF(E14>=0.8,"주의","안정")) -> 안정 | G14: =REPT("█",ROUND(MIN(1,E14)*10,0))&REPT("░",10-ROUND(MIN(1,E14)*10,0)) -> ░░░░░░░░░░ | I14: 1) 내역 시트에 뱅샐 내역을 복붙하면 자동 집계됩니다.
A15: 식비 | B15: 800000 | C15: =IFERROR(ABS(SUMIFS('내역'!E:E,'내역'!C:C,"식비",'내역'!A:A,">="&DATE('연간현황'!B3,1,1),'내역'!A:A,"<="&EOMONTH(DATE('연간현황'!B3,1,1),0))),0) -> 0 | D15: =B15-C15 -> 800000 | E15: =IFERROR(C15/B15,0) -> 0 | F15: =IF(E15>=1,"초과",IF(E15>=0.8,"주의","안정")) -> 안정 | G15: =REPT("█",ROUND(MIN(1,E15)*10,0))&REPT("░",10-ROUND(MIN(1,E15)*10,0)) -> ░░░░░░░░░░ | I15: 2) 사용률 80% 이상은 주의, 100% 이상은 초과입니다.
A16: 육아 | B16: 300000 | C16: =IFERROR(ABS(SUMIFS('내역'!E:E,'내역'!C:C,"육아",'내역'!A:A,">="&DATE('연간현황'!B3,1,1),'내역'!A:A,"<="&EOMONTH(DATE('연간현황'!B3,1,1),0))),0) -> 0 | D16: =B16-C16 -> 300000 | E16: =IFERROR(C16/B16,0) -> 0 | F16: =IF(E16>=1,"초과",IF(E16>=0.8,"주의","안정")) -> 안정 | G16: =REPT("█",ROUND(MIN(1,E16)*10,0))&REPT("░",10-ROUND(MIN(1,E16)*10,0)) -> ░░░░░░░░░░ | I16: 3) 위험 TOP3를 보고 다음 주 소비를 조절하세요.
A17: 의료비 | B17: 150000 | C17: =IFERROR(ABS(SUMIFS('내역'!E:E,'내역'!C:C,"의료비",'내역'!A:A,">="&DATE('연간현황'!B3,1,1),'내역'!A:A,"<="&EOMONTH(DATE('연간현황'!B3,1,1),0))),0) -> 0 | D17: =B17-C17 -> 150000 | E17: =IFERROR(C17/B17,0) -> 0 | F17: =IF(E17>=1,"초과",IF(E17>=0.8,"주의","안정")) -> 안정 | G17: =REPT("█",ROUND(MIN(1,E17)*10,0))&REPT("░",10-ROUND(MIN(1,E17)*10,0)) -> ░░░░░░░░░░ | I17: 4) 내역 금액은 원 단위, 월별 시트는 만원 단위로 자동 환산됩니다.
A18: 기타생활비 | B18: 300000 | C18: =IFERROR(ABS(SUMIFS('내역'!E:E,'내역'!C:C,"기타생활비",'내역'!A:A,">="&DATE('연간현황'!B3,1,1),'내역'!A:A,"<="&EOMONTH(DATE('연간현황'!B3,1,1),0))),0) -> 0 | D18: =B18-C18 -> 300000 | E18: =IFERROR(C18/B18,0) -> 0 | F18: =IF(E18>=1,"초과",IF(E18>=0.8,"주의","안정")) -> 안정 | G18: =REPT("█",ROUND(MIN(1,E18)*10,0))&REPT("░",10-ROUND(MIN(1,E18)*10,0)) -> ░░░░░░░░░░
A19: 이벤트 | B19: 100000 | C19: =IFERROR(ABS(SUMIFS('내역'!E:E,'내역'!C:C,"이벤트",'내역'!A:A,">="&DATE('연간현황'!B3,1,1),'내역'!A:A,"<="&EOMONTH(DATE('연간현황'!B3,1,1),0))),0) -> 0 | D19: =B19-C19 -> 100000 | E19: =IFERROR(C19/B19,0) -> 0 | F19: =IF(E19>=1,"초과",IF(E19>=0.8,"주의","안정")) -> 안정 | G19: =REPT("█",ROUND(MIN(1,E19)*10,0))&REPT("░",10-ROUND(MIN(1,E19)*10,0)) -> ░░░░░░░░░░
A20: 기석용돈 | B20: 250000 | C20: =IFERROR(ABS(SUMIFS('내역'!E:E,'내역'!C:C,"기석용돈",'내역'!A:A,">="&DATE('연간현황'!B3,1,1),'내역'!A:A,"<="&EOMONTH(DATE('연간현황'!B3,1,1),0))),0) -> 0 | D20: =B20-C20 -> 250000 | E20: =IFERROR(C20/B20,0) -> 0 | F20: =IF(E20>=1,"초과",IF(E20>=0.8,"주의","안정")) -> 안정 | G20: =REPT("█",ROUND(MIN(1,E20)*10,0))&REPT("░",10-ROUND(MIN(1,E20)*10,0)) -> ░░░░░░░░░░
A21: 승주용돈 | B21: 250000 | C21: =IFERROR(ABS(SUMIFS('내역'!E:E,'내역'!C:C,"승주용돈",'내역'!A:A,">="&DATE('연간현황'!B3,1,1),'내역'!A:A,"<="&EOMONTH(DATE('연간현황'!B3,1,1),0))),0) -> 0 | D21: =B21-C21 -> 250000 | E21: =IFERROR(C21/B21,0) -> 0 | F21: =IF(E21>=1,"초과",IF(E21>=0.8,"주의","안정")) -> 안정 | G21: =REPT("█",ROUND(MIN(1,E21)*10,0))&REPT("░",10-ROUND(MIN(1,E21)*10,0)) -> ░░░░░░░░░░
A22: 합계 | B22: =SUM(B8:B21) -> 6940000 | C22: =SUM(C8:C21) -> 0 | D22: =SUM(D8:D21) -> 6940000 | E22: =IFERROR(C22/B22,0) -> 0 | F22: =IF(E22>=1,"초과",IF(E22>=0.8,"주의","안정")) -> 안정 | G22: =REPT("█",ROUND(MIN(1,E22)*10,0))&REPT("░",10-ROUND(MIN(1,E22)*10,0)) -> ░░░░░░░░░░

Sheet 02월
A1: 02월 한도 관리
A2: 내역 시트에 복붙하면 자동 집계됩니다. 단위: 원
A4: 월 예산 | B4: =B22 -> 6940000 | C4: 월 사용 | D4: =C22 -> 0 | E4: 잔여 | F4: =D22 -> 6940000 | G4: 총 사용률 | H4: =IFERROR(C22/B22,0) -> 0
A7: 항목 | B7: 예산 | C7: 사용 | D7: 남은금액 | E7: 사용률 | F7: 상태 | G7: 진행바 | I7: 위험 TOP3
A8: 대출 | B8: 2900000 | C8: =IFERROR(ABS(SUMIFS('내역'!E:E,'내역'!C:C,"대출",'내역'!A:A,">="&DATE('연간현황'!B3,2,1),'내역'!A:A,"<="&EOMONTH(DATE('연간현황'!B3,2,1),0))),0) -> 0 | D8: =B8-C8 -> 2900000 | E8: =IFERROR(C8/B8,0) -> 0 | F8: =IF(E8>=1,"초과",IF(E8>=0.8,"주의","안정")) -> 안정 | G8: =REPT("█",ROUND(MIN(1,E8)*10,0))&REPT("░",10-ROUND(MIN(1,E8)*10,0)) -> ░░░░░░░░░░ | I8: 순위 | J8: 항목 | K8: 사용률 | L8: 남은금액
A9: 보험 | B9: 550000 | C9: =IFERROR(ABS(SUMIFS('내역'!E:E,'내역'!C:C,"보험",'내역'!A:A,">="&DATE('연간현황'!B3,2,1),'내역'!A:A,"<="&EOMONTH(DATE('연간현황'!B3,2,1),0))),0) -> 0 | D9: =B9-C9 -> 550000 | E9: =IFERROR(C9/B9,0) -> 0 | F9: =IF(E9>=1,"초과",IF(E9>=0.8,"주의","안정")) -> 안정 | G9: =REPT("█",ROUND(MIN(1,E9)*10,0))&REPT("░",10-ROUND(MIN(1,E9)*10,0)) -> ░░░░░░░░░░ | I9: 1 | J9: {=INDEX($A$8:$A$21,MATCH(LARGE($E$8:$E$21,1),$E$8:$E$21,0))} -> 대출 | K9: =LARGE($E$8:$E$21,1) -> 0 | L9: {=INDEX($D$8:$D$21,MATCH(LARGE($E$8:$E$21,1),$E$8:$E$21,0))} -> 2900000
A10: 통신비 | B10: 140000 | C10: =IFERROR(ABS(SUMIFS('내역'!E:E,'내역'!C:C,"통신비",'내역'!A:A,">="&DATE('연간현황'!B3,2,1),'내역'!A:A,"<="&EOMONTH(DATE('연간현황'!B3,2,1),0))),0) -> 0 | D10: =B10-C10 -> 140000 | E10: =IFERROR(C10/B10,0) -> 0 | F10: =IF(E10>=1,"초과",IF(E10>=0.8,"주의","안정")) -> 안정 | G10: =REPT("█",ROUND(MIN(1,E10)*10,0))&REPT("░",10-ROUND(MIN(1,E10)*10,0)) -> ░░░░░░░░░░ | I10: 2 | J10: {=INDEX($A$8:$A$21,MATCH(LARGE($E$8:$E$21,2),$E$8:$E$21,0))} -> 대출 | K10: =LARGE($E$8:$E$21,2) -> 0 | L10: {=INDEX($D$8:$D$21,MATCH(LARGE($E$8:$E$21,2),$E$8:$E$21,0))} -> 2900000
A11: 주거비 | B11: 210000 | C11: =IFERROR(ABS(SUMIFS('내역'!E:E,'내역'!C:C,"주거비",'내역'!A:A,">="&DATE('연간현황'!B3,2,1),'내역'!A:A,"<="&EOMONTH(DATE('연간현황'!B3,2,1),0))),0) -> 0 | D11: =B11-C11 -> 210000 | E11: =IFERROR(C11/B11,0) -> 0 | F11: =IF(E11>=1,"초과",IF(E11>=0.8,"주의","안정")) -> 안정 | G11: =REPT("█",ROUND(MIN(1,E11)*10,0))&REPT("░",10-ROUND(MIN(1,E11)*10,0)) -> ░░░░░░░░░░ | I11: 3 | J11: {=INDEX($A$8:$A$21,MATCH(LARGE($E$8:$E$21,3),$E$8:$E$21,0))} -> 대출 | K11: =LARGE($E$8:$E$21,3) -> 0 | L11: {=INDEX($D$8:$D$21,MATCH(LARGE($E$8:$E$21,3),$E$8:$E$21,0))} -> 2900000
A12: 생활고정비 | B12: 260000 | C12: =IFERROR(ABS(SUMIFS('내역'!E:E,'내역'!C:C,"생활고정비",'내역'!A:A,">="&DATE('연간현황'!B3,2,1),'내역'!A:A,"<="&EOMONTH(DATE('연간현황'!B3,2,1),0))),0) -> 0 | D12: =B12-C12 -> 260000 | E12: =IFERROR(C12/B12,0) -> 0 | F12: =IF(E12>=1,"초과",IF(E12>=0.8,"주의","안정")) -> 안정 | G12: =REPT("█",ROUND(MIN(1,E12)*10,0))&REPT("░",10-ROUND(MIN(1,E12)*10,0)) -> ░░░░░░░░░░
A13: 금융고정비 | B13: 580000 | C13: =IFERROR(ABS(SUMIFS('내역'!E:E,'내역'!C:C,"금융고정비",'내역'!A:A,">="&DATE('연간현황'!B3,2,1),'내역'!A:A,"<="&EOMONTH(DATE('연간현황'!B3,2,1),0))),0) -> 0 | D13: =B13-C13 -> 580000 | E13: =IFERROR(C13/B13,0) -> 0 | F13: =IF(E13>=1,"초과",IF(E13>=0.8,"주의","안정")) -> 안정 | G13: =REPT("█",ROUND(MIN(1,E13)*10,0))&REPT("░",10-ROUND(MIN(1,E13)*10,0)) -> ░░░░░░░░░░ | I13: 작성법
A14: 교통 | B14: 150000 | C14: =IFERROR(ABS(SUMIFS('내역'!E:E,'내역'!C:C,"교통",'내역'!A:A,">="&DATE('연간현황'!B3,2,1),'내역'!A:A,"<="&EOMONTH(DATE('연간현황'!B3,2,1),0))),0) -> 0 | D14: =B14-C14 -> 150000 | E14: =IFERROR(C14/B14,0) -> 0 | F14: =IF(E14>=1,"초과",IF(E14>=0.8,"주의","안정")) -> 안정 | G14: =REPT("█",ROUND(MIN(1,E14)*10,0))&REPT("░",10-ROUND(MIN(1,E14)*10,0)) -> ░░░░░░░░░░ | I14: 1) 내역 시트에 뱅샐 내역을 복붙하면 자동 집계됩니다.
A15: 식비 | B15: 800000 | C15: =IFERROR(ABS(SUMIFS('내역'!E:E,'내역'!C:C,"식비",'내역'!A:A,">="&DATE('연간현황'!B3,2,1),'내역'!A:A,"<="&EOMONTH(DATE('연간현황'!B3,2,1),0))),0) -> 0 | D15: =B15-C15 -> 800000 | E15: =IFERROR(C15/B15,0) -> 0 | F15: =IF(E15>=1,"초과",IF(E15>=0.8,"주의","안정")) -> 안정 | G15: =REPT("█",ROUND(MIN(1,E15)*10,0))&REPT("░",10-ROUND(MIN(1,E15)*10,0)) -> ░░░░░░░░░░ | I15: 2) 사용률 80% 이상은 주의, 100% 이상은 초과입니다.
A16: 육아 | B16: 300000 | C16: =IFERROR(ABS(SUMIFS('내역'!E:E,'내역'!C:C,"육아",'내역'!A:A,">="&DATE('연간현황'!B3,2,1),'내역'!A:A,"<="&EOMONTH(DATE('연간현황'!B3,2,1),0))),0) -> 0 | D16: =B16-C16 -> 300000 | E16: =IFERROR(C16/B16,0) -> 0 | F16: =IF(E16>=1,"초과",IF(E16>=0.8,"주의","안정")) -> 안정 | G16: =REPT("█",ROUND(MIN(1,E16)*10,0))&REPT("░",10-ROUND(MIN(1,E16)*10,0)) -> ░░░░░░░░░░ | I16: 3) 위험 TOP3를 보고 다음 주 소비를 조절하세요.
A17: 의료비 | B17: 150000 | C17: =IFERROR(ABS(SUMIFS('내역'!E:E,'내역'!C:C,"의료비",'내역'!A:A,">="&DATE('연간현황'!B3,2,1),'내역'!A:A,"<="&EOMONTH(DATE('연간현황'!B3,2,1),0))),0) -> 0 | D17: =B17-C17 -> 150000 | E17: =IFERROR(C17/B17,0) -> 0 | F17: =IF(E17>=1,"초과",IF(E17>=0.8,"주의","안정")) -> 안정 | G17: =REPT("█",ROUND(MIN(1,E17)*10,0))&REPT("░",10-ROUND(MIN(1,E17)*10,0)) -> ░░░░░░░░░░ | I17: 4) 내역 금액은 원 단위, 월별 시트는 만원 단위로 자동 환산됩니다.
A18: 기타생활비 | B18: 300000 | C18: =IFERROR(ABS(SUMIFS('내역'!E:E,'내역'!C:C,"기타생활비",'내역'!A:A,">="&DATE('연간현황'!B3,2,1),'내역'!A:A,"<="&EOMONTH(DATE('연간현황'!B3,2,1),0))),0) -> 0 | D18: =B18-C18 -> 300000 | E18: =IFERROR(C18/B18,0) -> 0 | F18: =IF(E18>=1,"초과",IF(E18>=0.8,"주의","안정")) -> 안정 | G18: =REPT("█",ROUND(MIN(1,E18)*10,0))&REPT("░",10-ROUND(MIN(1,E18)*10,0)) -> ░░░░░░░░░░
A19: 이벤트 | B19: 100000 | C19: =IFERROR(ABS(SUMIFS('내역'!E:E,'내역'!C:C,"이벤트",'내역'!A:A,">="&DATE('연간현황'!B3,2,1),'내역'!A:A,"<="&EOMONTH(DATE('연간현황'!B3,2,1),0))),0) -> 0 | D19: =B19-C19 -> 100000 | E19: =IFERROR(C19/B19,0) -> 0 | F19: =IF(E19>=1,"초과",IF(E19>=0.8,"주의","안정")) -> 안정 | G19: =REPT("█",ROUND(MIN(1,E19)*10,0))&REPT("░",10-ROUND(MIN(1,E19)*10,0)) -> ░░░░░░░░░░
A20: 기석용돈 | B20: 250000 | C20: =IFERROR(ABS(SUMIFS('내역'!E:E,'내역'!C:C,"기석용돈",'내역'!A:A,">="&DATE('연간현황'!B3,2,1),'내역'!A:A,"<="&EOMONTH(DATE('연간현황'!B3,2,1),0))),0) -> 0 | D20: =B20-C20 -> 250000 | E20: =IFERROR(C20/B20,0) -> 0 | F20: =IF(E20>=1,"초과",IF(E20>=0.8,"주의","안정")) -> 안정 | G20: =REPT("█",ROUND(MIN(1,E20)*10,0))&REPT("░",10-ROUND(MIN(1,E20)*10,0)) -> ░░░░░░░░░░
A21: 승주용돈 | B21: 250000 | C21: =IFERROR(ABS(SUMIFS('내역'!E:E,'내역'!C:C,"승주용돈",'내역'!A:A,">="&DATE('연간현황'!B3,2,1),'내역'!A:A,"<="&EOMONTH(DATE('연간현황'!B3,2,1),0))),0) -> 0 | D21: =B21-C21 -> 250000 | E21: =IFERROR(C21/B21,0) -> 0 | F21: =IF(E21>=1,"초과",IF(E21>=0.8,"주의","안정")) -> 안정 | G21: =REPT("█",ROUND(MIN(1,E21)*10,0))&REPT("░",10-ROUND(MIN(1,E21)*10,0)) -> ░░░░░░░░░░
A22: 합계 | B22: =SUM(B8:B21) -> 6940000 | C22: =SUM(C8:C21) -> 0 | D22: =SUM(D8:D21) -> 6940000 | E22: =IFERROR(C22/B22,0) -> 0 | F22: =IF(E22>=1,"초과",IF(E22>=0.8,"주의","안정")) -> 안정 | G22: =REPT("█",ROUND(MIN(1,E22)*10,0))&REPT("░",10-ROUND(MIN(1,E22)*10,0)) -> ░░░░░░░░░░

Sheet 03월
A1: 03월 한도 관리
A2: 내역 시트에 복붙하면 자동 집계됩니다. 단위: 원
A4: 월 예산 | B4: =B22 -> 6940000 | C4: 월 사용 | D4: =C22 -> 0 | E4: 잔여 | F4: =D22 -> 6940000 | G4: 총 사용률 | H4: =IFERROR(C22/B22,0) -> 0
A7: 항목 | B7: 예산 | C7: 사용 | D7: 남은금액 | E7: 사용률 | F7: 상태 | G7: 진행바 | I7: 위험 TOP3
A8: 대출 | B8: 2900000 | C8: =IFERROR(ABS(SUMIFS('내역'!E:E,'내역'!C:C,"대출",'내역'!A:A,">="&DATE('연간현황'!B3,3,1),'내역'!A:A,"<="&EOMONTH(DATE('연간현황'!B3,3,1),0))),0) -> 0 | D8: =B8-C8 -> 2900000 | E8: =IFERROR(C8/B8,0) -> 0 | F8: =IF(E8>=1,"초과",IF(E8>=0.8,"주의","안정")) -> 안정 | G8: =REPT("█",ROUND(MIN(1,E8)*10,0))&REPT("░",10-ROUND(MIN(1,E8)*10,0)) -> ░░░░░░░░░░ | I8: 순위 | J8: 항목 | K8: 사용률 | L8: 남은금액
A9: 보험 | B9: 550000 | C9: =IFERROR(ABS(SUMIFS('내역'!E:E,'내역'!C:C,"보험",'내역'!A:A,">="&DATE('연간현황'!B3,3,1),'내역'!A:A,"<="&EOMONTH(DATE('연간현황'!B3,3,1),0))),0) -> 0 | D9: =B9-C9 -> 550000 | E9: =IFERROR(C9/B9,0) -> 0 | F9: =IF(E9>=1,"초과",IF(E9>=0.8,"주의","안정")) -> 안정 | G9: =REPT("█",ROUND(MIN(1,E9)*10,0))&REPT("░",10-ROUND(MIN(1,E9)*10,0)) -> ░░░░░░░░░░ | I9: 1 | J9: {=INDEX($A$8:$A$21,MATCH(LARGE($E$8:$E$21,1),$E$8:$E$21,0))} -> 대출 | K9: =LARGE($E$8:$E$21,1) -> 0 | L9: {=INDEX($D$8:$D$21,MATCH(LARGE($E$8:$E$21,1),$E$8:$E$21,0))} -> 2900000
A10: 통신비 | B10: 140000 | C10: =IFERROR(ABS(SUMIFS('내역'!E:E,'내역'!C:C,"통신비",'내역'!A:A,">="&DATE('연간현황'!B3,3,1),'내역'!A:A,"<="&EOMONTH(DATE('연간현황'!B3,3,1),0))),0) -> 0 | D10: =B10-C10 -> 140000 | E10: =IFERROR(C10/B10,0) -> 0 | F10: =IF(E10>=1,"초과",IF(E10>=0.8,"주의","안정")) -> 안정 | G10: =REPT("█",ROUND(MIN(1,E10)*10,0))&REPT("░",10-ROUND(MIN(1,E10)*10,0)) -> ░░░░░░░░░░ | I10: 2 | J10: {=INDEX($A$8:$A$21,MATCH(LARGE($E$8:$E$21,2),$E$8:$E$21,0))} -> 대출 | K10: =LARGE($E$8:$E$21,2) -> 0 | L10: {=INDEX($D$8:$D$21,MATCH(LARGE($E$8:$E$21,2),$E$8:$E$21,0))} -> 2900000
A11: 주거비 | B11: 210000 | C11: =IFERROR(ABS(SUMIFS('내역'!E:E,'내역'!C:C,"주거비",'내역'!A:A,">="&DATE('연간현황'!B3,3,1),'내역'!A:A,"<="&EOMONTH(DATE('연간현황'!B3,3,1),0))),0) -> 0 | D11: =B11-C11 -> 210000 | E11: =IFERROR(C11/B11,0) -> 0 | F11: =IF(E11>=1,"초과",IF(E11>=0.8,"주의","안정")) -> 안정 | G11: =REPT("█",ROUND(MIN(1,E11)*10,0))&REPT("░",10-ROUND(MIN(1,E11)*10,0)) -> ░░░░░░░░░░ | I11: 3 | J11: {=INDEX($A$8:$A$21,MATCH(LARGE($E$8:$E$21,3),$E$8:$E$21,0))} -> 대출 | K11: =LARGE($E$8:$E$21,3) -> 0 | L11: {=INDEX($D$8:$D$21,MATCH(LARGE($E$8:$E$21,3),$E$8:$E$21,0))} -> 2900000
A12: 생활고정비 | B12: 260000 | C12: =IFERROR(ABS(SUMIFS('내역'!E:E,'내역'!C:C,"생활고정비",'내역'!A:A,">="&DATE('연간현황'!B3,3,1),'내역'!A:A,"<="&EOMONTH(DATE('연간현황'!B3,3,1),0))),0) -> 0 | D12: =B12-C12 -> 260000 | E12: =IFERROR(C12/B12,0) -> 0 | F12: =IF(E12>=1,"초과",IF(E12>=0.8,"주의","안정")) -> 안정 | G12: =REPT("█",ROUND(MIN(1,E12)*10,0))&REPT("░",10-ROUND(MIN(1,E12)*10,0)) -> ░░░░░░░░░░
A13: 금융고정비 | B13: 580000 | C13: =IFERROR(ABS(SUMIFS('내역'!E:E,'내역'!C:C,"금융고정비",'내역'!A:A,">="&DATE('연간현황'!B3,3,1),'내역'!A:A,"<="&EOMONTH(DATE('연간현황'!B3,3,1),0))),0) -> 0 | D13: =B13-C13 -> 580000 | E13: =IFERROR(C13/B13,0) -> 0 | F13: =IF(E13>=1,"초과",IF(E13>=0.8,"주의","안정")) -> 안정 | G13: =REPT("█",ROUND(MIN(1,E13)*10,0))&REPT("░",10-ROUND(MIN(1,E13)*10,0)) -> ░░░░░░░░░░ | I13: 작성법
A14: 교통 | B14: 150000 | C14: =IFERROR(ABS(SUMIFS('내역'!E:E,'내역'!C:C,"교통",'내역'!A:A,">="&DATE('연간현황'!B3,3,1),'내역'!A:A,"<="&EOMONTH(DATE('연간현황'!B3,3,1),0))),0) -> 0 | D14: =B14-C14 -> 150000 | E14: =IFERROR(C14/B14,0) -> 0 | F14: =IF(E14>=1,"초과",IF(E14>=0.8,"주의","안정")) -> 안정 | G14: =REPT("█",ROUND(MIN(1,E14)*10,0))&REPT("░",10-ROUND(MIN(1,E14)*10,0)) -> ░░░░░░░░░░ | I14: 1) 내역 시트에 뱅샐 내역을 복붙하면 자동 집계됩니다.
A15: 식비 | B15: 800000 | C15: =IFERROR(ABS(SUMIFS('내역'!E:E,'내역'!C:C,"식비",'내역'!A:A,">="&DATE('연간현황'!B3,3,1),'내역'!A:A,"<="&EOMONTH(DATE('연간현황'!B3,3,1),0))),0) -> 0 | D15: =B15-C15 -> 800000 | E15: =IFERROR(C15/B15,0) -> 0 | F15: =IF(E15>=1,"초과",IF(E15>=0.8,"주의","안정")) -> 안정 | G15: =REPT("█",ROUND(MIN(1,E15)*10,0))&REPT("░",10-ROUND(MIN(1,E15)*10,0)) -> ░░░░░░░░░░ | I15: 2) 사용률 80% 이상은 주의, 100% 이상은 초과입니다.
A16: 육아 | B16: 300000 | C16: =IFERROR(ABS(SUMIFS('내역'!E:E,'내역'!C:C,"육아",'내역'!A:A,">="&DATE('연간현황'!B3,3,1),'내역'!A:A,"<="&EOMONTH(DATE('연간현황'!B3,3,1),0))),0) -> 0 | D16: =B16-C16 -> 300000 | E16: =IFERROR(C16/B16,0) -> 0 | F16: =IF(E16>=1,"초과",IF(E16>=0.8,"주의","안정")) -> 안정 | G16: =REPT("█",ROUND(MIN(1,E16)*10,0))&REPT("░",10-ROUND(MIN(1,E16)*10,0)) -> ░░░░░░░░░░ | I16: 3) 위험 TOP3를 보고 다음 주 소비를 조절하세요.
A17: 의료비 | B17: 150000 | C17: =IFERROR(ABS(SUMIFS('내역'!E:E,'내역'!C:C,"의료비",'내역'!A:A,">="&DATE('연간현황'!B3,3,1),'내역'!A:A,"<="&EOMONTH(DATE('연간현황'!B3,3,1),0))),0) -> 0 | D17: =B17-C17 -> 150000 | E17: =IFERROR(C17/B17,0) -> 0 | F17: =IF(E17>=1,"초과",IF(E17>=0.8,"주의","안정")) -> 안정 | G17: =REPT("█",ROUND(MIN(1,E17)*10,0))&REPT("░",10-ROUND(MIN(1,E17)*10,0)) -> ░░░░░░░░░░ | I17: 4) 내역 금액은 원 단위, 월별 시트는 만원 단위로 자동 환산됩니다.
A18: 기타생활비 | B18: 300000 | C18: =IFERROR(ABS(SUMIFS('내역'!E:E,'내역'!C:C,"기타생활비",'내역'!A:A,">="&DATE('연간현황'!B3,3,1),'내역'!A:A,"<="&EOMONTH(DATE('연간현황'!B3,3,1),0))),0) -> 0 | D18: =B18-C18 -> 300000 | E18: =IFERROR(C18/B18,0) -> 0 | F18: =IF(E18>=1,"초과",IF(E18>=0.8,"주의","안정")) -> 안정 | G18: =REPT("█",ROUND(MIN(1,E18)*10,0))&REPT("░",10-ROUND(MIN(1,E18)*10,0)) -> ░░░░░░░░░░
A19: 이벤트 | B19: 100000 | C19: =IFERROR(ABS(SUMIFS('내역'!E:E,'내역'!C:C,"이벤트",'내역'!A:A,">="&DATE('연간현황'!B3,3,1),'내역'!A:A,"<="&EOMONTH(DATE('연간현황'!B3,3,1),0))),0) -> 0 | D19: =B19-C19 -> 100000 | E19: =IFERROR(C19/B19,0) -> 0 | F19: =IF(E19>=1,"초과",IF(E19>=0.8,"주의","안정")) -> 안정 | G19: =REPT("█",ROUND(MIN(1,E19)*10,0))&REPT("░",10-ROUND(MIN(1,E19)*10,0)) -> ░░░░░░░░░░
A20: 기석용돈 | B20: 250000 | C20: =IFERROR(ABS(SUMIFS('내역'!E:E,'내역'!C:C,"기석용돈",'내역'!A:A,">="&DATE('연간현황'!B3,3,1),'내역'!A:A,"<="&EOMONTH(DATE('연간현황'!B3,3,1),0))),0) -> 0 | D20: =B20-C20 -> 250000 | E20: =IFERROR(C20/B20,0) -> 0 | F20: =IF(E20>=1,"초과",IF(E20>=0.8,"주의","안정")) -> 안정 | G20: =REPT("█",ROUND(MIN(1,E20)*10,0))&REPT("░",10-ROUND(MIN(1,E20)*10,0)) -> ░░░░░░░░░░
A21: 승주용돈 | B21: 250000 | C21: =IFERROR(ABS(SUMIFS('내역'!E:E,'내역'!C:C,"승주용돈",'내역'!A:A,">="&DATE('연간현황'!B3,3,1),'내역'!A:A,"<="&EOMONTH(DATE('연간현황'!B3,3,1),0))),0) -> 0 | D21: =B21-C21 -> 250000 | E21: =IFERROR(C21/B21,0) -> 0 | F21: =IF(E21>=1,"초과",IF(E21>=0.8,"주의","안정")) -> 안정 | G21: =REPT("█",ROUND(MIN(1,E21)*10,0))&REPT("░",10-ROUND(MIN(1,E21)*10,0)) -> ░░░░░░░░░░
A22: 합계 | B22: =SUM(B8:B21) -> 6940000 | C22: =SUM(C8:C21) -> 0 | D22: =SUM(D8:D21) -> 6940000 | E22: =IFERROR(C22/B22,0) -> 0 | F22: =IF(E22>=1,"초과",IF(E22>=0.8,"주의","안정")) -> 안정 | G22: =REPT("█",ROUND(MIN(1,E22)*10,0))&REPT("░",10-ROUND(MIN(1,E22)*10,0)) -> ░░░░░░░░░░

Sheet 04월
A1: 04월 한도 관리
A2: 내역 시트에 복붙하면 자동 집계됩니다. 단위: 원
A4: 월 예산 | B4: =B22 -> 6940000 | C4: 월 사용 | D4: =C22 -> 0 | E4: 잔여 | F4: =D22 -> 6940000 | G4: 총 사용률 | H4: =IFERROR(C22/B22,0) -> 0
A7: 항목 | B7: 예산 | C7: 사용 | D7: 남은금액 | E7: 사용률 | F7: 상태 | G7: 진행바 | I7: 위험 TOP3
A8: 대출 | B8: 2900000 | C8: =IFERROR(ABS(SUMIFS('내역'!E:E,'내역'!C:C,"대출",'내역'!A:A,">="&DATE('연간현황'!B3,4,1),'내역'!A:A,"<="&EOMONTH(DATE('연간현황'!B3,4,1),0))),0) -> 0 | D8: =B8-C8 -> 2900000 | E8: =IFERROR(C8/B8,0) -> 0 | F8: =IF(E8>=1,"초과",IF(E8>=0.8,"주의","안정")) -> 안정 | G8: =REPT("█",ROUND(MIN(1,E8)*10,0))&REPT("░",10-ROUND(MIN(1,E8)*10,0)) -> ░░░░░░░░░░ | I8: 순위 | J8: 항목 | K8: 사용률 | L8: 남은금액
A9: 보험 | B9: 550000 | C9: =IFERROR(ABS(SUMIFS('내역'!E:E,'내역'!C:C,"보험",'내역'!A:A,">="&DATE('연간현황'!B3,4,1),'내역'!A:A,"<="&EOMONTH(DATE('연간현황'!B3,4,1),0))),0) -> 0 | D9: =B9-C9 -> 550000 | E9: =IFERROR(C9/B9,0) -> 0 | F9: =IF(E9>=1,"초과",IF(E9>=0.8,"주의","안정")) -> 안정 | G9: =REPT("█",ROUND(MIN(1,E9)*10,0))&REPT("░",10-ROUND(MIN(1,E9)*10,0)) -> ░░░░░░░░░░ | I9: 1 | J9: {=INDEX($A$8:$A$21,MATCH(LARGE($E$8:$E$21,1),$E$8:$E$21,0))} -> 대출 | K9: =LARGE($E$8:$E$21,1) -> 0 | L9: {=INDEX($D$8:$D$21,MATCH(LARGE($E$8:$E$21,1),$E$8:$E$21,0))} -> 2900000
A10: 통신비 | B10: 140000 | C10: =IFERROR(ABS(SUMIFS('내역'!E:E,'내역'!C:C,"통신비",'내역'!A:A,">="&DATE('연간현황'!B3,4,1),'내역'!A:A,"<="&EOMONTH(DATE('연간현황'!B3,4,1),0))),0) -> 0 | D10: =B10-C10 -> 140000 | E10: =IFERROR(C10/B10,0) -> 0 | F10: =IF(E10>=1,"초과",IF(E10>=0.8,"주의","안정")) -> 안정 | G10: =REPT("█",ROUND(MIN(1,E10)*10,0))&REPT("░",10-ROUND(MIN(1,E10)*10,0)) -> ░░░░░░░░░░ | I10: 2 | J10: {=INDEX($A$8:$A$21,MATCH(LARGE($E$8:$E$21,2),$E$8:$E$21,0))} -> 대출 | K10: =LARGE($E$8:$E$21,2) -> 0 | L10: {=INDEX($D$8:$D$21,MATCH(LARGE($E$8:$E$21,2),$E$8:$E$21,0))} -> 2900000
A11: 주거비 | B11: 210000 | C11: =IFERROR(ABS(SUMIFS('내역'!E:E,'내역'!C:C,"주거비",'내역'!A:A,">="&DATE('연간현황'!B3,4,1),'내역'!A:A,"<="&EOMONTH(DATE('연간현황'!B3,4,1),0))),0) -> 0 | D11: =B11-C11 -> 210000 | E11: =IFERROR(C11/B11,0) -> 0 | F11: =IF(E11>=1,"초과",IF(E11>=0.8,"주의","안정")) -> 안정 | G11: =REPT("█",ROUND(MIN(1,E11)*10,0))&REPT("░",10-ROUND(MIN(1,E11)*10,0)) -> ░░░░░░░░░░ | I11: 3 | J11: {=INDEX($A$8:$A$21,MATCH(LARGE($E$8:$E$21,3),$E$8:$E$21,0))} -> 대출 | K11: =LARGE($E$8:$E$21,3) -> 0 | L11: {=INDEX($D$8:$D$21,MATCH(LARGE($E$8:$E$21,3),$E$8:$E$21,0))} -> 2900000
A12: 생활고정비 | B12: 260000 | C12: =IFERROR(ABS(SUMIFS('내역'!E:E,'내역'!C:C,"생활고정비",'내역'!A:A,">="&DATE('연간현황'!B3,4,1),'내역'!A:A,"<="&EOMONTH(DATE('연간현황'!B3,4,1),0))),0) -> 0 | D12: =B12-C12 -> 260000 | E12: =IFERROR(C12/B12,0) -> 0 | F12: =IF(E12>=1,"초과",IF(E12>=0.8,"주의","안정")) -> 안정 | G12: =REPT("█",ROUND(MIN(1,E12)*10,0))&REPT("░",10-ROUND(MIN(1,E12)*10,0)) -> ░░░░░░░░░░
A13: 금융고정비 | B13: 580000 | C13: =IFERROR(ABS(SUMIFS('내역'!E:E,'내역'!C:C,"금융고정비",'내역'!A:A,">="&DATE('연간현황'!B3,4,1),'내역'!A:A,"<="&EOMONTH(DATE('연간현황'!B3,4,1),0))),0) -> 0 | D13: =B13-C13 -> 580000 | E13: =IFERROR(C13/B13,0) -> 0 | F13: =IF(E13>=1,"초과",IF(E13>=0.8,"주의","안정")) -> 안정 | G13: =REPT("█",ROUND(MIN(1,E13)*10,0))&REPT("░",10-ROUND(MIN(1,E13)*10,0)) -> ░░░░░░░░░░ | I13: 작성법
A14: 교통 | B14: 150000 | C14: =IFERROR(ABS(SUMIFS('내역'!E:E,'내역'!C:C,"교통",'내역'!A:A,">="&DATE('연간현황'!B3,4,1),'내역'!A:A,"<="&EOMONTH(DATE('연간현황'!B3,4,1),0))),0) -> 0 | D14: =B14-C14 -> 150000 | E14: =IFERROR(C14/B14,0) -> 0 | F14: =IF(E14>=1,"초과",IF(E14>=0.8,"주의","안정")) -> 안정 | G14: =REPT("█",ROUND(MIN(1,E14)*10,0))&REPT("░",10-ROUND(MIN(1,E14)*10,0)) -> ░░░░░░░░░░ | I14: 1) 내역 시트에 뱅샐 내역을 복붙하면 자동 집계됩니다.
A15: 식비 | B15: 800000 | C15: =IFERROR(ABS(SUMIFS('내역'!E:E,'내역'!C:C,"식비",'내역'!A:A,">="&DATE('연간현황'!B3,4,1),'내역'!A:A,"<="&EOMONTH(DATE('연간현황'!B3,4,1),0))),0) -> 0 | D15: =B15-C15 -> 800000 | E15: =IFERROR(C15/B15,0) -> 0 | F15: =IF(E15>=1,"초과",IF(E15>=0.8,"주의","안정")) -> 안정 | G15: =REPT("█",ROUND(MIN(1,E15)*10,0))&REPT("░",10-ROUND(MIN(1,E15)*10,0)) -> ░░░░░░░░░░ | I15: 2) 사용률 80% 이상은 주의, 100% 이상은 초과입니다.
A16: 육아 | B16: 300000 | C16: =IFERROR(ABS(SUMIFS('내역'!E:E,'내역'!C:C,"육아",'내역'!A:A,">="&DATE('연간현황'!B3,4,1),'내역'!A:A,"<="&EOMONTH(DATE('연간현황'!B3,4,1),0))),0) -> 0 | D16: =B16-C16 -> 300000 | E16: =IFERROR(C16/B16,0) -> 0 | F16: =IF(E16>=1,"초과",IF(E16>=0.8,"주의","안정")) -> 안정 | G16: =REPT("█",ROUND(MIN(1,E16)*10,0))&REPT("░",10-ROUND(MIN(1,E16)*10,0)) -> ░░░░░░░░░░ | I16: 3) 위험 TOP3를 보고 다음 주 소비를 조절하세요.
A17: 의료비 | B17: 150000 | C17: =IFERROR(ABS(SUMIFS('내역'!E:E,'내역'!C:C,"의료비",'내역'!A:A,">="&DATE('연간현황'!B3,4,1),'내역'!A:A,"<="&EOMONTH(DATE('연간현황'!B3,4,1),0))),0) -> 0 | D17: =B17-C17 -> 150000 | E17: =IFERROR(C17/B17,0) -> 0 | F17: =IF(E17>=1,"초과",IF(E17>=0.8,"주의","안정")) -> 안정 | G17: =REPT("█",ROUND(MIN(1,E17)*10,0))&REPT("░",10-ROUND(MIN(1,E17)*10,0)) -> ░░░░░░░░░░ | I17: 4) 내역 금액은 원 단위, 월별 시트는 만원 단위로 자동 환산됩니다.
A18: 기타생활비 | B18: 300000 | C18: =IFERROR(ABS(SUMIFS('내역'!E:E,'내역'!C:C,"기타생활비",'내역'!A:A,">="&DATE('연간현황'!B3,4,1),'내역'!A:A,"<="&EOMONTH(DATE('연간현황'!B3,4,1),0))),0) -> 0 | D18: =B18-C18 -> 300000 | E18: =IFERROR(C18/B18,0) -> 0 | F18: =IF(E18>=1,"초과",IF(E18>=0.8,"주의","안정")) -> 안정 | G18: =REPT("█",ROUND(MIN(1,E18)*10,0))&REPT("░",10-ROUND(MIN(1,E18)*10,0)) -> ░░░░░░░░░░
A19: 이벤트 | B19: 100000 | C19: =IFERROR(ABS(SUMIFS('내역'!E:E,'내역'!C:C,"이벤트",'내역'!A:A,">="&DATE('연간현황'!B3,4,1),'내역'!A:A,"<="&EOMONTH(DATE('연간현황'!B3,4,1),0))),0) -> 0 | D19: =B19-C19 -> 100000 | E19: =IFERROR(C19/B19,0) -> 0 | F19: =IF(E19>=1,"초과",IF(E19>=0.8,"주의","안정")) -> 안정 | G19: =REPT("█",ROUND(MIN(1,E19)*10,0))&REPT("░",10-ROUND(MIN(1,E19)*10,0)) -> ░░░░░░░░░░
A20: 기석용돈 | B20: 250000 | C20: =IFERROR(ABS(SUMIFS('내역'!E:E,'내역'!C:C,"기석용돈",'내역'!A:A,">="&DATE('연간현황'!B3,4,1),'내역'!A:A,"<="&EOMONTH(DATE('연간현황'!B3,4,1),0))),0) -> 0 | D20: =B20-C20 -> 250000 | E20: =IFERROR(C20/B20,0) -> 0 | F20: =IF(E20>=1,"초과",IF(E20>=0.8,"주의","안정")) -> 안정 | G20: =REPT("█",ROUND(MIN(1,E20)*10,0))&REPT("░",10-ROUND(MIN(1,E20)*10,0)) -> ░░░░░░░░░░
A21: 승주용돈 | B21: 250000 | C21: =IFERROR(ABS(SUMIFS('내역'!E:E,'내역'!C:C,"승주용돈",'내역'!A:A,">="&DATE('연간현황'!B3,4,1),'내역'!A:A,"<="&EOMONTH(DATE('연간현황'!B3,4,1),0))),0) -> 0 | D21: =B21-C21 -> 250000 | E21: =IFERROR(C21/B21,0) -> 0 | F21: =IF(E21>=1,"초과",IF(E21>=0.8,"주의","안정")) -> 안정 | G21: =REPT("█",ROUND(MIN(1,E21)*10,0))&REPT("░",10-ROUND(MIN(1,E21)*10,0)) -> ░░░░░░░░░░
A22: 합계 | B22: =SUM(B8:B21) -> 6940000 | C22: =SUM(C8:C21) -> 0 | D22: =SUM(D8:D21) -> 6940000 | E22: =IFERROR(C22/B22,0) -> 0 | F22: =IF(E22>=1,"초과",IF(E22>=0.8,"주의","안정")) -> 안정 | G22: =REPT("█",ROUND(MIN(1,E22)*10,0))&REPT("░",10-ROUND(MIN(1,E22)*10,0)) -> ░░░░░░░░░░

Sheet 05월
A1: 05월 한도 관리
A2: 내역 시트에 복붙하면 자동 집계됩니다. 단위: 원
A4: 월 예산 | B4: =B22 -> 6940000 | C4: 월 사용 | D4: =C22 -> 5285894 | E4: 잔여 | F4: =D22 -> 1654106 | G4: 총 사용률 | H4: =IFERROR(C22/B22,0) -> 0.7616562
A7: 항목 | B7: 예산 | C7: 사용 | D7: 남은금액 | E7: 사용률 | F7: 상태 | G7: 진행바 | I7: 위험 TOP3
A8: 대출 | B8: 2900000 | C8: =IFERROR(ABS(SUMIFS('내역'!E:E,'내역'!C:C,"대출",'내역'!A:A,">="&DATE('연간현황'!B3,5,1),'내역'!A:A,"<="&EOMONTH(DATE('연간현황'!B3,5,1),0))),0) -> 1203242 | D8: =B8-C8 -> 1696758 | E8: =IFERROR(C8/B8,0) -> 0.41491103 | F8: =IF(E8>=1,"초과",IF(E8>=0.8,"주의","안정")) -> 안정 | G8: =REPT("█",ROUND(MIN(1,E8)*10,0))&REPT("░",10-ROUND(MIN(1,E8)*10,0)) -> ████░░░░░░ | I8: 순위 | J8: 항목 | K8: 사용률 | L8: 남은금액
A9: 보험 | B9: 550000 | C9: =IFERROR(ABS(SUMIFS('내역'!E:E,'내역'!C:C,"보험",'내역'!A:A,">="&DATE('연간현황'!B3,5,1),'내역'!A:A,"<="&EOMONTH(DATE('연간현황'!B3,5,1),0))),0) -> 396911 | D9: =B9-C9 -> 153089 | E9: =IFERROR(C9/B9,0) -> 0.72165636 | F9: =IF(E9>=1,"초과",IF(E9>=0.8,"주의","안정")) -> 안정 | G9: =REPT("█",ROUND(MIN(1,E9)*10,0))&REPT("░",10-ROUND(MIN(1,E9)*10,0)) -> ███████░░░ | I9: 1 | J9: {=INDEX($A$8:$A$21,MATCH(LARGE($E$8:$E$21,1),$E$8:$E$21,0))} -> 이벤트 | K9: =LARGE($E$8:$E$21,1) -> 2.67499 | L9: {=INDEX($D$8:$D$21,MATCH(LARGE($E$8:$E$21,1),$E$8:$E$21,0))} -> -167499
A10: 통신비 | B10: 140000 | C10: =IFERROR(ABS(SUMIFS('내역'!E:E,'내역'!C:C,"통신비",'내역'!A:A,">="&DATE('연간현황'!B3,5,1),'내역'!A:A,"<="&EOMONTH(DATE('연간현황'!B3,5,1),0))),0) -> 159530 | D10: =B10-C10 -> -19530 | E10: =IFERROR(C10/B10,0) -> 1.1395 | F10: =IF(E10>=1,"초과",IF(E10>=0.8,"주의","안정")) -> 초과 | G10: =REPT("█",ROUND(MIN(1,E10)*10,0))&REPT("░",10-ROUND(MIN(1,E10)*10,0)) -> ██████████ | I10: 2 | J10: {=INDEX($A$8:$A$21,MATCH(LARGE($E$8:$E$21,2),$E$8:$E$21,0))} -> 육아 | K10: =LARGE($E$8:$E$21,2) -> 2.4549633 | L10: {=INDEX($D$8:$D$21,MATCH(LARGE($E$8:$E$21,2),$E$8:$E$21,0))} -> -436489
A11: 주거비 | B11: 210000 | C11: =IFERROR(ABS(SUMIFS('내역'!E:E,'내역'!C:C,"주거비",'내역'!A:A,">="&DATE('연간현황'!B3,5,1),'내역'!A:A,"<="&EOMONTH(DATE('연간현황'!B3,5,1),0))),0) -> 199150 | D11: =B11-C11 -> 10850 | E11: =IFERROR(C11/B11,0) -> 0.94833333 | F11: =IF(E11>=1,"초과",IF(E11>=0.8,"주의","안정")) -> 주의 | G11: =REPT("█",ROUND(MIN(1,E11)*10,0))&REPT("░",10-ROUND(MIN(1,E11)*10,0)) -> █████████░ | I11: 3 | J11: {=INDEX($A$8:$A$21,MATCH(LARGE($E$8:$E$21,3),$E$8:$E$21,0))} -> 식비 | K11: =LARGE($E$8:$E$21,3) -> 1.1752537 | L11: {=INDEX($D$8:$D$21,MATCH(LARGE($E$8:$E$21,3),$E$8:$E$21,0))} -> -140203
A12: 생활고정비 | B12: 260000 | C12: =IFERROR(ABS(SUMIFS('내역'!E:E,'내역'!C:C,"생활고정비",'내역'!A:A,">="&DATE('연간현황'!B3,5,1),'내역'!A:A,"<="&EOMONTH(DATE('연간현황'!B3,5,1),0))),0) -> 202190 | D12: =B12-C12 -> 57810 | E12: =IFERROR(C12/B12,0) -> 0.77765385 | F12: =IF(E12>=1,"초과",IF(E12>=0.8,"주의","안정")) -> 안정 | G12: =REPT("█",ROUND(MIN(1,E12)*10,0))&REPT("░",10-ROUND(MIN(1,E12)*10,0)) -> ████████░░
A13: 금융고정비 | B13: 580000 | C13: =IFERROR(ABS(SUMIFS('내역'!E:E,'내역'!C:C,"금융고정비",'내역'!A:A,">="&DATE('연간현황'!B3,5,1),'내역'!A:A,"<="&EOMONTH(DATE('연간현황'!B3,5,1),0))),0) -> 580300 | D13: =B13-C13 -> -300 | E13: =IFERROR(C13/B13,0) -> 1.0005172 | F13: =IF(E13>=1,"초과",IF(E13>=0.8,"주의","안정")) -> 초과 | G13: =REPT("█",ROUND(MIN(1,E13)*10,0))&REPT("░",10-ROUND(MIN(1,E13)*10,0)) -> ██████████ | I13: 작성법
A14: 교통 | B14: 150000 | C14: =IFERROR(ABS(SUMIFS('내역'!E:E,'내역'!C:C,"교통",'내역'!A:A,">="&DATE('연간현황'!B3,5,1),'내역'!A:A,"<="&EOMONTH(DATE('연간현황'!B3,5,1),0))),0) -> 137100 | D14: =B14-C14 -> 12900 | E14: =IFERROR(C14/B14,0) -> 0.914 | F14: =IF(E14>=1,"초과",IF(E14>=0.8,"주의","안정")) -> 주의 | G14: =REPT("█",ROUND(MIN(1,E14)*10,0))&REPT("░",10-ROUND(MIN(1,E14)*10,0)) -> █████████░ | I14: 1) 내역 시트에 뱅샐 내역을 복붙하면 자동 집계됩니다.
A15: 식비 | B15: 800000 | C15: =IFERROR(ABS(SUMIFS('내역'!E:E,'내역'!C:C,"식비",'내역'!A:A,">="&DATE('연간현황'!B3,5,1),'내역'!A:A,"<="&EOMONTH(DATE('연간현황'!B3,5,1),0))),0) -> 940203 | D15: =B15-C15 -> -140203 | E15: =IFERROR(C15/B15,0) -> 1.1752537 | F15: =IF(E15>=1,"초과",IF(E15>=0.8,"주의","안정")) -> 초과 | G15: =REPT("█",ROUND(MIN(1,E15)*10,0))&REPT("░",10-ROUND(MIN(1,E15)*10,0)) -> ██████████ | I15: 2) 사용률 80% 이상은 주의, 100% 이상은 초과입니다.
A16: 육아 | B16: 300000 | C16: =IFERROR(ABS(SUMIFS('내역'!E:E,'내역'!C:C,"육아",'내역'!A:A,">="&DATE('연간현황'!B3,5,1),'내역'!A:A,"<="&EOMONTH(DATE('연간현황'!B3,5,1),0))),0) -> 736489 | D16: =B16-C16 -> -436489 | E16: =IFERROR(C16/B16,0) -> 2.4549633 | F16: =IF(E16>=1,"초과",IF(E16>=0.8,"주의","안정")) -> 초과 | G16: =REPT("█",ROUND(MIN(1,E16)*10,0))&REPT("░",10-ROUND(MIN(1,E16)*10,0)) -> ██████████ | I16: 3) 위험 TOP3를 보고 다음 주 소비를 조절하세요.
A17: 의료비 | B17: 150000 | C17: =MAX(0, IFERROR(ABS(SUMIFS('내역'!E:E,'내역'!C:C,"의료비",'내역'!A:A,">="&DATE('연간현황'!B3,5,1),'내역'!A:A,"<="&EOMONTH(DATE('연간현황'!B3,5,1),0)))-ABS(SUMIFS('내역'!E:E,'내역'!C:C,"실비",'내역'!A:A,">="&DATE('연간현황'!B3,5,1),'내역'!A:A,"<="&EOMONTH(DATE('연간현황'!B3,5,1),0))),0)) -> 0 | D17: =B17-C17 -> 150000 | E17: =IFERROR(C17/B17,0) -> 0 | F17: =IF(E17>=1,"초과",IF(E17>=0.8,"주의","안정")) -> 안정 | G17: =REPT("█",ROUND(MIN(1,E17)*10,0))&REPT("░",10-ROUND(MIN(1,E17)*10,0)) -> ░░░░░░░░░░ | I17: 4) 내역 금액은 원 단위, 월별 시트는 만원 단위로 자동 환산됩니다.
A18: 기타생활비 | B18: 300000 | C18: =IFERROR(ABS(SUMIFS('내역'!E:E,'내역'!C:C,"기타생활비",'내역'!A:A,">="&DATE('연간현황'!B3,5,1),'내역'!A:A,"<="&EOMONTH(DATE('연간현황'!B3,5,1),0))),0) -> 143380 | D18: =B18-C18 -> 156620 | E18: =IFERROR(C18/B18,0) -> 0.47793333 | F18: =IF(E18>=1,"초과",IF(E18>=0.8,"주의","안정")) -> 안정 | G18: =REPT("█",ROUND(MIN(1,E18)*10,0))&REPT("░",10-ROUND(MIN(1,E18)*10,0)) -> █████░░░░░
A19: 이벤트 | B19: 100000 | C19: =IFERROR(ABS(SUMIFS('내역'!E:E,'내역'!C:C,"이벤트",'내역'!A:A,">="&DATE('연간현황'!B3,5,1),'내역'!A:A,"<="&EOMONTH(DATE('연간현황'!B3,5,1),0))),0) -> 267499 | D19: =B19-C19 -> -167499 | E19: =IFERROR(C19/B19,0) -> 2.67499 | F19: =IF(E19>=1,"초과",IF(E19>=0.8,"주의","안정")) -> 초과 | G19: =REPT("█",ROUND(MIN(1,E19)*10,0))&REPT("░",10-ROUND(MIN(1,E19)*10,0)) -> ██████████
A20: 기석용돈 | B20: 250000 | C20: =IFERROR(ABS(SUMIFS('내역'!E:E,'내역'!C:C,"기석용돈",'내역'!A:A,">="&DATE('연간현황'!B3,5,1),'내역'!A:A,"<="&EOMONTH(DATE('연간현황'!B3,5,1),0))),0) -> 196600 | D20: =B20-C20 -> 53400 | E20: =IFERROR(C20/B20,0) -> 0.7864 | F20: =IF(E20>=1,"초과",IF(E20>=0.8,"주의","안정")) -> 안정 | G20: =REPT("█",ROUND(MIN(1,E20)*10,0))&REPT("░",10-ROUND(MIN(1,E20)*10,0)) -> ████████░░
A21: 승주용돈 | B21: 250000 | C21: =IFERROR(ABS(SUMIFS('내역'!E:E,'내역'!C:C,"승주용돈",'내역'!A:A,">="&DATE('연간현황'!B3,5,1),'내역'!A:A,"<="&EOMONTH(DATE('연간현황'!B3,5,1),0))),0) -> 123300 | D21: =B21-C21 -> 126700 | E21: =IFERROR(C21/B21,0) -> 0.4932 | F21: =IF(E21>=1,"초과",IF(E21>=0.8,"주의","안정")) -> 안정 | G21: =REPT("█",ROUND(MIN(1,E21)*10,0))&REPT("░",10-ROUND(MIN(1,E21)*10,0)) -> █████░░░░░
A22: 합계 | B22: =SUM(B8:B21) -> 6940000 | C22: =SUM(C8:C21) -> 5285894 | D22: =SUM(D8:D21) -> 1654106 | E22: =IFERROR(C22/B22,0) -> 0.7616562 | F22: =IF(E22>=1,"초과",IF(E22>=0.8,"주의","안정")) -> 안정 | G22: =REPT("█",ROUND(MIN(1,E22)*10,0))&REPT("░",10-ROUND(MIN(1,E22)*10,0)) -> ████████░░

Sheet 06월
A1: 06월 한도 관리
A2: 내역 시트에 복붙하면 자동 집계됩니다. 단위: 원
A4: 월 예산 | B4: =B22 -> 6780000 | C4: 월 사용 | D4: =C22 -> 5901764 | E4: 잔여 | F4: =D22 -> 878236 | G4: 총 사용률 | H4: =IFERROR(C22/B22,0) -> 0.87046667
A7: 항목 | B7: 예산 | C7: 사용 | D7: 남은금액 | E7: 사용률 | F7: 상태 | G7: 진행바 | I7: 위험 TOP3
A8: 대출 | B8: 2900000 | C8: =IFERROR(ABS(SUMIFS('내역'!E:E,'내역'!C:C,"대출",'내역'!A:A,">="&DATE('연간현황'!B3,6,1),'내역'!A:A,"<="&EOMONTH(DATE('연간현황'!B3,6,1),0))),0) -> 1192505 | D8: =B8-C8 -> 1707495 | E8: =IFERROR(C8/B8,0) -> 0.41120862 | F8: =IF(E8>=1,"초과",IF(E8>=0.8,"주의","안정")) -> 안정 | G8: =REPT("█",ROUND(MIN(1,E8)*10,0))&REPT("░",10-ROUND(MIN(1,E8)*10,0)) -> ████░░░░░░ | I8: 순위 | J8: 항목 | K8: 사용률 | L8: 남은금액
A9: 보험 | B9: 550000 | C9: =IFERROR(ABS(SUMIFS('내역'!E:E,'내역'!C:C,"보험",'내역'!A:A,">="&DATE('연간현황'!B3,6,1),'내역'!A:A,"<="&EOMONTH(DATE('연간현황'!B3,6,1),0))),0) -> 598295 | D9: =B9-C9 -> -48295 | E9: =IFERROR(C9/B9,0) -> 1.0878091 | F9: =IF(E9>=1,"초과",IF(E9>=0.8,"주의","안정")) -> 초과 | G9: =REPT("█",ROUND(MIN(1,E9)*10,0))&REPT("░",10-ROUND(MIN(1,E9)*10,0)) -> ██████████ | I9: 1 | J9: {=INDEX($A$8:$A$21,MATCH(LARGE($E$8:$E$21,1),$E$8:$E$21,0))} -> 이벤트 | K9: =LARGE($E$8:$E$21,1) -> 2.773 | L9: {=INDEX($D$8:$D$21,MATCH(LARGE($E$8:$E$21,1),$E$8:$E$21,0))} -> -177300
A10: 통신비 | B10: 140000 | C10: =IFERROR(ABS(SUMIFS('내역'!E:E,'내역'!C:C,"통신비",'내역'!A:A,">="&DATE('연간현황'!B3,6,1),'내역'!A:A,"<="&EOMONTH(DATE('연간현황'!B3,6,1),0))),0) -> 146940 | D10: =B10-C10 -> -6940 | E10: =IFERROR(C10/B10,0) -> 1.0495714 | F10: =IF(E10>=1,"초과",IF(E10>=0.8,"주의","안정")) -> 초과 | G10: =REPT("█",ROUND(MIN(1,E10)*10,0))&REPT("░",10-ROUND(MIN(1,E10)*10,0)) -> ██████████ | I10: 2 | J10: {=INDEX($A$8:$A$21,MATCH(LARGE($E$8:$E$21,2),$E$8:$E$21,0))} -> 의료비 | K10: =LARGE($E$8:$E$21,2) -> 2.3140733 | L10: {=INDEX($D$8:$D$21,MATCH(LARGE($E$8:$E$21,2),$E$8:$E$21,0))} -> -197111
A11: 주거비 | B11: 210000 | C11: =IFERROR(ABS(SUMIFS('내역'!E:E,'내역'!C:C,"주거비",'내역'!A:A,">="&DATE('연간현황'!B3,6,1),'내역'!A:A,"<="&EOMONTH(DATE('연간현황'!B3,6,1),0))),0) -> 195220 | D11: =B11-C11 -> 14780 | E11: =IFERROR(C11/B11,0) -> 0.92961905 | F11: =IF(E11>=1,"초과",IF(E11>=0.8,"주의","안정")) -> 주의 | G11: =REPT("█",ROUND(MIN(1,E11)*10,0))&REPT("░",10-ROUND(MIN(1,E11)*10,0)) -> █████████░ | I11: 3 | J11: {=INDEX($A$8:$A$21,MATCH(LARGE($E$8:$E$21,3),$E$8:$E$21,0))} -> 육아 | K11: =LARGE($E$8:$E$21,3) -> 2.141665 | L11: {=INDEX($D$8:$D$21,MATCH(LARGE($E$8:$E$21,3),$E$8:$E$21,0))} -> -456666
A12: 생활고정비 | B12: 260000 | C12: =IFERROR(ABS(SUMIFS('내역'!E:E,'내역'!C:C,"생활고정비",'내역'!A:A,">="&DATE('연간현황'!B3,6,1),'내역'!A:A,"<="&EOMONTH(DATE('연간현황'!B3,6,1),0))),0) -> 249190 | D12: =B12-C12 -> 10810 | E12: =IFERROR(C12/B12,0) -> 0.95842308 | F12: =IF(E12>=1,"초과",IF(E12>=0.8,"주의","안정")) -> 주의 | G12: =REPT("█",ROUND(MIN(1,E12)*10,0))&REPT("░",10-ROUND(MIN(1,E12)*10,0)) -> ██████████
A13: 금융고정비 | B13: 420000 | C13: =IFERROR(ABS(SUMIFS('내역'!E:E,'내역'!C:C,"금융고정비",'내역'!A:A,">="&DATE('연간현황'!B3,6,1),'내역'!A:A,"<="&EOMONTH(DATE('연간현황'!B3,6,1),0))),0) -> 420300 | D13: =B13-C13 -> -300 | E13: =IFERROR(C13/B13,0) -> 1.0007143 | F13: =IF(E13>=1,"초과",IF(E13>=0.8,"주의","안정")) -> 초과 | G13: =REPT("█",ROUND(MIN(1,E13)*10,0))&REPT("░",10-ROUND(MIN(1,E13)*10,0)) -> ██████████ | I13: 작성법
A14: 교통 | B14: 150000 | C14: =IFERROR(ABS(SUMIFS('내역'!E:E,'내역'!C:C,"교통",'내역'!A:A,">="&DATE('연간현황'!B3,6,1),'내역'!A:A,"<="&EOMONTH(DATE('연간현황'!B3,6,1),0))),0) -> 178225 | D14: =B14-C14 -> -28225 | E14: =IFERROR(C14/B14,0) -> 1.1881667 | F14: =IF(E14>=1,"초과",IF(E14>=0.8,"주의","안정")) -> 초과 | G14: =REPT("█",ROUND(MIN(1,E14)*10,0))&REPT("░",10-ROUND(MIN(1,E14)*10,0)) -> ██████████ | I14: 1) 내역 시트에 뱅샐 내역을 복붙하면 자동 집계됩니다.
A15: 식비 | B15: 800000 | C15: =IFERROR(ABS(SUMIFS('내역'!E:E,'내역'!C:C,"식비",'내역'!A:A,">="&DATE('연간현황'!B3,6,1),'내역'!A:A,"<="&EOMONTH(DATE('연간현황'!B3,6,1),0))),0) -> 1060428 | D15: =B15-C15 -> -260428 | E15: =IFERROR(C15/B15,0) -> 1.325535 | F15: =IF(E15>=1,"초과",IF(E15>=0.8,"주의","안정")) -> 초과 | G15: =REPT("█",ROUND(MIN(1,E15)*10,0))&REPT("░",10-ROUND(MIN(1,E15)*10,0)) -> ██████████ | I15: 2) 사용률 80% 이상은 주의, 100% 이상은 초과입니다.
A16: 육아 | B16: 400000 | C16: =IFERROR(ABS(SUMIFS('내역'!E:E,'내역'!C:C,"육아",'내역'!A:A,">="&DATE('연간현황'!B3,6,1),'내역'!A:A,"<="&EOMONTH(DATE('연간현황'!B3,6,1),0))),0) -> 856666 | D16: =B16-C16 -> -456666 | E16: =IFERROR(C16/B16,0) -> 2.141665 | F16: =IF(E16>=1,"초과",IF(E16>=0.8,"주의","안정")) -> 초과 | G16: =REPT("█",ROUND(MIN(1,E16)*10,0))&REPT("░",10-ROUND(MIN(1,E16)*10,0)) -> ██████████ | I16: 3) 위험 TOP3를 보고 다음 주 소비를 조절하세요.
A17: 의료비 | B17: 150000 | C17: =MAX(0, IFERROR(ABS(SUMIFS('내역'!E:E,'내역'!C:C,"의료비",'내역'!A:A,">="&DATE('연간현황'!B3,6,1),'내역'!A:A,"<="&EOMONTH(DATE('연간현황'!B3,6,1),0)))-ABS(SUMIFS('내역'!E:E,'내역'!C:C,"실비",'내역'!A:A,">="&DATE('연간현황'!B3,6,1),'내역'!A:A,"<="&EOMONTH(DATE('연간현황'!B3,6,1),0))),0)) -> 347111 | D17: =B17-C17 -> -197111 | E17: =IFERROR(C17/B17,0) -> 2.3140733 | F17: =IF(E17>=1,"초과",IF(E17>=0.8,"주의","안정")) -> 초과 | G17: =REPT("█",ROUND(MIN(1,E17)*10,0))&REPT("░",10-ROUND(MIN(1,E17)*10,0)) -> ██████████ | I17: 4) 내역 금액은 원 단위, 월별 시트는 만원 단위로 자동 환산됩니다.
A18: 기타생활비 | B18: 300000 | C18: =IFERROR(ABS(SUMIFS('내역'!E:E,'내역'!C:C,"기타생활비",'내역'!A:A,">="&DATE('연간현황'!B3,6,1),'내역'!A:A,"<="&EOMONTH(DATE('연간현황'!B3,6,1),0))),0) -> 180176 | D18: =B18-C18 -> 119824 | E18: =IFERROR(C18/B18,0) -> 0.60058667 | F18: =IF(E18>=1,"초과",IF(E18>=0.8,"주의","안정")) -> 안정 | G18: =REPT("█",ROUND(MIN(1,E18)*10,0))&REPT("░",10-ROUND(MIN(1,E18)*10,0)) -> ██████░░░░
